Workbook

Sheet APP拉新-留存
C1: BI | D1: BI | G1: BI | I1: BI | K1: gp后台 | L1: gp后台 | M1: aso工具 | N1: aso工具 | O1: AS后台 | P1: AS后台 | Q1: aso工具 | R1: aso工具 | S1: AF | T1: 手机端安卓IOS访问网页用户数 | U1: BI手动
C2: APP自然北极星 | G2: APP留存 | K2: Google play | O2: AppleStore | S2: FX官网
A3: 周数 | B3: 地区 | C3: 自然北极星 | D3: 自然下载 | E3: 老用户日活 | F3: 下载/日活 | G3: 自然次留 | H3: 自然次留率 | I3: 自然日活 | J3: 北极星/日活 | K3: google下载页面访问量 | L3: Google安装量 | M3: 关键词TOP3量 | N3: 关键词覆盖量 | O3: apple下载页面访问量 | P3: Apple安装量 | Q3: 关键词TOP3量 | R3: 关键词覆盖量 | S3: AF官网自然下载 | T3: 官网手机端自然uv | U3: 下载资源位点击人数 | V3: 下载资源位点击率
A4: 2025-6/30~7/4 | B4: 印度/巴基斯坦 | C4: 64.2 | D4: 58 | E4: =I4-D4 -> 65 | F4: =D4/I4 -> 0.47154472 | G4: 7 | H4: =G4/D4 -> 0.12068966 | I4: 123 | J4: =C4/I4 -> 0.52195122 | S4: 0.8 | T4: 763.8 | U4: \N
A5: 2025-6/30~7/4 | B5: 印尼 | C5: 78.4 | D5: 37.4 | E5: =I5-D5 -> 63.6 | F5: =D5/I5 -> 0.37029703 | G5: 5.8 | H5: =G5/D5 -> 0.15508021 | I5: 101 | J5: =C5/I5 -> 0.77623762 | S5: 2.6 | T5: 615.2 | U5: \N
A6: 2025-6/30~7/4 | B6: 总计 | C6: =C4+C5 -> 142.6 | D6: =D4+D5 -> 95.4 | E6: =I6-D6 -> 128.6 | F6: =D6/I6 -> 0.42589286 | G6: =G4+G5 -> 12.8 | H6: =G6/D6 -> 0.13417191 | I6: =I4+I5 -> 224 | J6: =C6/I6 -> 0.63660714 | S6: =S4+S5 -> 3.4 | T6: =T4+T5 -> 1379
A7: 2025-7/7~7/11 | B7: 印度/巴基斯坦 | C7: 75 | D7: 60 | E7: =I7-D7 -> 67.2 | F7: =D7/I7 -> 0.47169811 | G7: 6.6 | H7: =G7/D7 -> 0.11 | I7: 127.2 | J7: =C7/I7 -> 0.58962264 | S7: 1.4 | T7: 795 | U7: \N
A8: 2025-7/7~7/11 | B8: 印尼 | C8: 96.2 | D8: 46.6 | E8: =I8-D8 -> 61.4 | F8: =D8/I8 -> 0.43148148 | G8: 10.8 | H8: =G8/D8 -> 0.23175966 | I8: 108 | J8: =C8/I8 -> 0.89074074 | S8: 1 | T8: 555.4 | U8: \N
A9: 2025-7/7~7/11 | B9: 总计 | C9: =C7+C8 -> 171.2 | D9: =D7+D8 -> 106.6 | E9: =I9-D9 -> 128.6 | F9: =D9/I9 -> 0.45323129 | G9: =G7+G8 -> 17.4 | H9: =G9/D9 -> 0.16322702 | I9: =I7+I8 -> 235.2 | J9: =C9/I9 -> 0.72789116 | S9: =S7+S8 -> 2.4 | T9: =T7+T8 -> 1350.4
A10: 2025-7/14~7/18 | B10: 印度/巴基斯坦 | C10: 102 | D10: 64.4 | E10: =I10-D10 -> 76.6 | F10: =D10/I10 -> 0.45673759 | G10: 6 | H10: =G10/D10 -> 0.093167702 | I10: 141 | J10: =C10/I10 -> 0.72340426 | S10: 0.4 | T10: 802.6 | U10: \N
A11: 2025-7/14~7/18 | B11: 印尼 | C11: 109.2 | D11: 59.6 | E11: =I11-D11 -> 73.2 | F11: =D11/I11 -> 0.44879518 | G11: 8.4 | H11: =G11/D11 -> 0.1409396 | I11: 132.8 | J11: =C11/I11 -> 0.82228916 | S11: 4 | T11: 649 | U11: \N
A12: 2025-7/14~7/18 | B12: 总计 | C12: =C10+C11 -> 211.2 | D12: =D10+D11 -> 124 | E12: =I12-D12 -> 149.8 | F12: =D12/I12 -> 0.45288532 | G12: =G10+G11 -> 14.4 | H12: =G12/D12 -> 0.11612903 | I12: =I10+I11 -> 273.8 | J12: =C12/I12 -> 0.77136596 | S12: =S10+S11 -> 4.4 | T12: =T10+T11 -> 1451.6
A13: 2025-7/21~7/25 | B13: 印度/巴基斯坦 | C13: 84.4 | D13: 60.2 | E13: =I13-D13 -> 74.6 | F13: =D13/I13 -> 0.44658754 | G13: 5.6 | H13: =G13/D13 -> 0.093023256 | I13: 134.8 | J13: =C13/I13 -> 0.62611276 | S13: 0.4 | T13: 842.8 | U13: \N
A14: 2025-7/21~7/25 | B14: 印尼 | C14: 122.8 | D14: 35.8 | E14: =I14-D14 -> 78.4 | F14: =D14/I14 -> 0.31348511 | G14: 8.2 | H14: =G14/D14 -> 0.22905028 | I14: 114.2 | J14: =C14/I14 -> 1.0753065 | S14: 1 | T14: 577 | U14: \N
A15: 2025-7/21~7/25 | B15: 总计 | C15: =C13+C14 -> 207.2 | D15: =D13+D14 -> 96 | E15: =I15-D15 -> 153 | F15: =D15/I15 -> 0.38554217 | G15: =G13+G14 -> 13.8 | H15: =G15/D15 -> 0.14375 | I15: =I13+I14 -> 249 | J15: =C15/I15 -> 0.83212851 | S15: =S13+S14 -> 1.4 | T15: =T13+T14 -> 1419.8
A16: 2025-7/28~8/1 | B16: 印度/巴基斯坦 | C16: 107.4 | D16: 75 | E16: =I16-D16 -> 77.4 | F16: =D16/I16 -> 0.49212598 | G16: 7 | H16: =G16/D16 -> 0.093333333 | I16: 152.4 | J16: =C16/I16 -> 0.70472441 | S16: 0.6 | T16: 982.6 | U16: \N
A17: 2025-7/28~8/1 | B17: 印尼 | C17: 109.2 | D17: 35.6 | E17: =I17-D17 -> 69.6 | F17: =D17/I17 -> 0.33840304 | G17: 6.8 | H17: =G17/D17 -> 0.19101124 | I17: 105.2 | J17: =C17/I17 -> 1.0380228 | S17: 1.6 | T17: 535.4 | U17: \N
A18: 2025-7/28~8/1 | B18: 总计 | C18: =C16+C17 -> 216.6 | D18: =D16+D17 -> 110.6 | E18: =I18-D18 -> 147 | F18: =D18/I18 -> 0.42934783 | G18: =G16+G17 -> 13.8 | H18: =G18/D18 -> 0.12477396 | I18: =I16+I17 -> 257.6 | J18: =C18/I18 -> 0.84083851 | S18: =S16+S17 -> 2.2 | T18: =T16+T17 -> 1518
A19: 2025-8/4~8/8 | B19: 印度/巴基斯坦 | C19: 104.6 | D19: 59.8 | E19: =I19-D19 -> 75.2 | F19: =D19/I19 -> 0.44296296 | G19: 6.2 | H19: =G19/D19 -> 0.10367893 | I19: 135 | J19: =C19/I19 -> 0.77481481 | S19: 1.2 | T19: 812 | U19: \N
A20: 2025-8/4~8/8 | B20: 印尼 | C20: 121.4 | D20: 42.4 | E20: =I20-D20 -> 76.8 | F20: =D20/I20 -> 0.3557047 | G20: 10 | H20: =G20/D20 -> 0.23584906 | I20: 119.2 | J20: =C20/I20 -> 1.0184564 | S20: 2 | T20: 530.8 | U20: \N
A21: 2025-8/4~8/8 | B21: 总计 | C21: =C19+C20 -> 226 | D21: =D19+D20 -> 102.2 | E21: =I21-D21 -> 152 | F21: =D21/I21 -> 0.40204563 | G21: =G19+G20 -> 16.2 | H21: =G21/D21 -> 0.15851272 | I21: =I19+I20 -> 254.2 | J21: =C21/I21 -> 0.88906373 | S21: =S19+S20 -> 3.2 | T21: =T19+T20 -> 1342.8
A22: 2025-8/11~8/15 | B22: 印度/巴基斯坦 | C22: 98 | D22: 38.8 | E22: =I22-D22 -> 77.8 | F22: =D22/I22 -> 0.33276158 | G22: 6.4 | H22: =G22/D22 -> 0.16494845 | I22: 116.6 | J22: =C22/I22 -> 0.84048027 | S22: 0.4 | T22: 840.8 | U22: \N
A23: 2025-8/11~8/15 | B23: 印尼 | C23: 128.4 | D23: 59.4 | E23: =I23-D23 -> 74.4 | F23: =D23/I23 -> 0.44394619 | G23: 14.8 | H23: =G23/D23 -> 0.24915825 | I23: 133.8 | J23: =C23/I23 -> 0.95964126 | S23: 3 | T23: 538.2 | U23: \N
A24: 2025-8/11~8/15 | B24: 总计 | C24: =C22+C23 -> 226.4 | D24: =D22+D23 -> 98.2 | E24: =I24-D24 -> 152.2 | F24: =D24/I24 -> 0.39217252 | G24: =G22+G23 -> 21.2 | H24: =G24/D24 -> 0.21588595 | I24: =I22+I23 -> 250.4 | J24: =C24/I24 -> 0.90415335 | S24: =S22+S23 -> 3.4 | T24: =T22+T23 -> 1379
A25: 2025-8/18~8/22 | B25: 印度/巴基斯坦 | C25: 105.8 | D25: 54.8 | E25: =I25-D25 -> 83 | F25: =D25/I25 -> 0.39767779 | G25: 5.8 | H25: =G25/D25 -> 0.10583942 | I25: 137.8 | J25: =C25/I25 -> 0.76777939 | S25: 0.2 | T25: 756 | U25: \N
A26: 2025-8/18~8/22 | B26: 印尼 | C26: 171 | D26: 72.2 | E26: =I26-D26 -> 95.2 | F26: =D26/I26 -> 0.43130227 | G26: 19.2 | H26: =G26/D26 -> 0.26592798 | I26: 167.4 | J26: =C26/I26 -> 1.0215054 | S26: 5.8 | T26: 600 | U26: \N
A27: 2025-8/18~8/22 | B27: 总计 | C27: =C25+C26 -> 276.8 | D27: =D25+D26 -> 127 | E27: =I27-D27 -> 178.2 | F27: =D27/I27 -> 0.41612058 | G27: =G25+G26 -> 25 | H27: =G27/D27 -> 0.19685039 | I27: =I25+I26 -> 305.2 | J27: =C27/I27 -> 0.90694626 | S27: =S25+S26 -> 6 | T27: =T25+T26 -> 1356
A28: 2025-8/25~8/29 | B28: 印度/巴基斯坦 | C28: 116.8 | D28: 51.2 | E28: =I28-D28 -> 80.2 | F28: =D28/I28 -> 0.38964992 | G28: 6.2 | H28: =G28/D28 -> 0.12109375 | I28: 131.4 | J28: =C28/I28 -> 0.88888889 | S28: 0.4 | T28: 875 | U28: \N
A29: 2025-8/25~8/29 | B29: 印尼 | C29: 146 | D29: 67.2 | E29: =I29-D29 -> 98.8 | F29: =D29/I29 -> 0.40481928 | G29: 13.4 | H29: =G29/D29 -> 0.19940476 | I29: 166 | J29: =C29/I29 -> 0.87951807 | S29: 3.6 | T29: 602.2 | U29: \N
A30: 2025-8/25~8/29 | B30: 总计 | C30: =C28+C29 -> 262.8 | D30: =D28+D29 -> 118.4 | E30: =I30-D30 -> 179 | F30: =D30/I30 -> 0.39811701 | G30: =G28+G29 -> 19.6 | H30: =G30/D30 -> 0.16554054 | I30: =I28+I29 -> 297.4 | J30: =C30/I30 -> 0.88365837 | S30: =S28+S29 -> 4 | T30: =T28+T29 -> 1477.2
A31: 2025-9/1~9/5 | B31: 印度/巴基斯坦 | C31: 89.2 | D31: 59.8 | E31: =I31-D31 -> 75 | F31: =D31/I31 -> 0.44362018 | G31: 6.6 | H31: =G31/D31 -> 0.11036789 | I31: 134.8 | J31: =C31/I31 -> 0.66172107 | S31: 0.6 | T31: 835 | U31: \N
A32: 2025-9/1~9/5 | B32: 印尼 | C32: 281 | D32: 91.6 | E32: =I32-D32 -> 162.6 | F32: =D32/I32 -> 0.36034618 | G32: 24.6 | H32: =G32/D32 -> 0.26855895 | I32: 254.2 | J32: =C32/I32 -> 1.1054288 | S32: 7.2 | T32: 2296.8 | U32: \N
A33: 2025-9/1~9/5 | B33: 总计 | C33: =C31+C32 -> 370.2 | D33: =D31+D32 -> 151.4 | E33: =I33-D33 -> 237.6 | F33: =D33/I33 -> 0.38920308 | G33: =G31+G32 -> 31.2 | H33: =G33/D33 -> 0.20607662 | I33: =I31+I32 -> 389 | J33: =C33/I33 -> 0.95167095 | S33: =S31+S32 -> 7.8 | T33: =T31+T32 -> 3131.8
A34: 2025-9/8~9/12 | B34: 印度/巴基斯坦 | C34: 129.6 | D34: 81.8 | E34: =I34-D34 -> 94.6 | F34: =D34/I34 -> 0.46371882 | G34: 10.4 | H34: =G34/D34 -> 0.12713936 | I34: 176.4 | J34: =C34/I34 -> 0.73469388 | S34: 0.8 | T34: 858 | U34: \N
A35: 2025-9/8~9/12 | B35: 印尼 | C35: 309.4 | D35: 145.8 | E35: =I35-D35 -> 145.4 | F35: =D35/I35 -> 0.50068681 | G35: 53.4 | H35: =G35/D35 -> 0.36625514 | I35: 291.2 | J35: =C35/I35 -> 1.0625 | S35: 11.8 | T35: 1298.4 | U35: \N
A36: 2025-9/8~9/12 | B36: 总计 | C36: =C34+C35 -> 439 | D36: =D34+D35 -> 227.6 | E36: =I36-D36 -> 240 | F36: =D36/I36 -> 0.4867408 | G36: =G34+G35 -> 63.8 | H36: =G36/D36 -> 0.28031634 | I36: =I34+I35 -> 467.6 | J36: =C36/I36 -> 0.93883661 | S36: =S34+S35 -> 12.6 | T36: =T34+T35 -> 2156.4
A37: 2025-9/15~9/19 | B37: 印度/巴基斯坦 | C37: 146.4 | D37: 79.4 | E37: =I37-D37 -> 102.8 | F37: =D37/I37 -> 0.43578485 | G37: 9.6 | H37: =G37/D37 -> 0.1209068 | I37: 182.2 | J37: =C37/I37 -> 0.80351262 | S37: 1.4 | T37: 807.8 | U37: \N
A38: 2025-9/15~9/19 | B38: 印尼 | C38: 217.8 | D38: 65.2 | E38: =I38-D38 -> 169.8 | F38: =D38/I38 -> 0.27744681 | G38: 15 | H38: =G38/D38 -> 0.23006135 | I38: 235 | J38: =C38/I38 -> 0.92680851 | S38: 5.8 | T38: 1100.6 | U38: \N
A39: 2025-9/15~9/19 | B39: 总计 | C39: =C37+C38 -> 364.2 | D39: =D37+D38 -> 144.6 | E39: =I39-D39 -> 272.6 | F39: =D39/I39 -> 0.34659636 | G39: =G37+G38 -> 24.6 | H39: =G39/D39 -> 0.17012448 | I39: =I37+I38 -> 417.2 | J39: =C39/I39 -> 0.87296261 | S39: =S37+S38 -> 7.2 | T39: =T37+T38 -> 1908.4
A40: 2025-9/22~9/26 | B40: 印度/巴基斯坦 | C40: 135.8 | D40: 91.8 | E40: =I40-D40 -> 106 | F40: =D40/I40 -> 0.46410516 | G40: 11.8 | H40: =G40/D40 -> 0.12854031 | I40: 197.8 | J40: =C40/I40 -> 0.68655207 | S40: 0.6 | T40: 783.8 | U40: \N
...

Sheet APP转化
E2: BI(基础数据日活) | F2: BI | I2: BI | L2: BI | M2: BI手动 | O2: BI | P2: BI手动(所有搜索框触发用户量) | R2: BI | T2: BI | V2: BI | W2: BI手动(icon) | Y2: BI | Z2: BI手动
I3: 商业内容 | L3: VPS活跃 | O3: 交易商搜索量 | R3: 交易商详情页 | T3: 交易商详情页外跳 | V3: 曝光内容 | Y3: 新闻内容
A4: 周数 | B4: 地区 | C4: 自然小BU | D4: 自然北极星 | E4: 日活 | F4: 访问7点位去重复人数 | G4: 7点位去重复人数/日活 | H4: 事件总数/7点位去重复人数 | I4: 商业页面访问数 | J4: 商业频道首页访问数 | K4: 商业/（日活+频道首页） | L4: VPS页面访问数 | M4: VPS频道首页访问数 | N4: VPS/（日活+频道首页） | O4: 搜索页面访问数 | P4: 搜索框访问量 | Q4: 搜索/（日活+频道首页） | R4: 交易商页面访问数 | S4: 交访/日活率 | T4: 交易商外跳点击数 | U4: 外跳/交访率 | V4: 曝光页面访问数 | W4: 曝光频道首页访问数 | X4: 曝光/（日活+频道首页） | Y4: 新闻页面访问数 | Z4: 新闻频道首页访问数 | AA4: 新闻/（日活+频道首页）
A5: 2025-6/30~7/4 | B5: 印度/巴基斯坦 | D5: 78.4 | E5: 123 | F5: 62.2 | G5: =F5/E5 -> 0.50569106 | H5: =(I5+L5+O5+R5+T5+V5+Y5)/F5 -> 1.5176849 | I5: 7.6 | J5: 8.4 | K5: =I5/(E5+J5) -> 0.057838661 | L5: 8.2 | M5: 6.2 | N5: =L5/(E5+M5) -> 0.063467492 | O5: 16.2 | P5: 29.6 | Q5: =O5/(E5+P5) -> 0.1061599 | R5: 38.6 | S5: =R5/E5 -> 0.31382114 | T5: 3.4 | U5: =T5/R5 -> 0.088082902 | V5: 2.4 | W5: 0 | X5: =V5/(E5+W5) -> 0.019512195 | Y5: 18 | Z5: 3.6 | AA5: =Y5/E5 -> 0.14634146
A6: 2025-6/30~7/4 | B6: 印尼 | D6: 64.2 | E6: 101 | F6: 68.2 | G6: =F6/E6 -> 0.67524752 | H6: =(I6+L6+O6+R6+T6+V6+Y6)/F6 -> 1.7653959 | I6: 5.6 | J6: 8 | K6: =I6/(E6+J6) -> 0.051376147 | L6: 15 | M6: 8.6 | N6: =L6/(E6+M6) -> 0.13686131 | O6: 11.6 | P6: 26.4 | Q6: =O6/(E6+P6) -> 0.091051805 | R6: 46.4 | S6: =R6/E6 -> 0.45940594 | T6: 16.2 | U6: =T6/R6 -> 0.34913793 | V6: 8.2 | W6: 0 | X6: =V6/(E6+W6) -> 0.081188119 | Y6: 17.4 | Z6: 3 | AA6: =Y6/E6 -> 0.17227723
A7: 2025-6/30~7/4 | B7: 总计 | D7: =D5+D6 -> 142.6 | E7: =E5+E6 -> 224 | F7: =F5+F6 -> 130.4 | G7: =F7/E7 -> 0.58214286 | H7: =(I7+L7+O7+R7+T7+V7+Y7)/F7 -> 1.6472393 | I7: =I5+I6 -> 13.2 | J7: =J5+J6 -> 16.4 | K7: =I7/(E7+J7) -> 0.054908486 | L7: =L5+L6 -> 23.2 | M7: =M5+M6 -> 14.8 | N7: =L7/(E7+M7) -> 0.097152429 | O7: =O5+O6 -> 27.8 | P7: =P5+P6 -> 56 | Q7: =O7/(E7+P7) -> 0.099285714 | R7: =R5+R6 -> 85 | S7: =R7/E7 -> 0.37946429 | T7: =T5+T6 -> 19.6 | U7: =T7/R7 -> 0.23058824 | V7: =V5+V6 -> 10.6 | W7: =W5+W6 -> 0 | X7: =V7/(E7+W7) -> 0.047321429 | Y7: =Y5+Y6 -> 35.4 | Z7: =Z5+Z6 -> 6.6 | AA7: =Y7/(E7+Z7) -> 0.15351258
A8: 2025-7/7~7/11 | B8: 印度/巴基斯坦 | D8: 96.2 | E8: 127.2 | F8: 60.8 | G8: =F8/E8 -> 0.47798742 | H8: =(I8+L8+O8+R8+T8+V8+Y8)/F8 -> 1.625 | I8: 6.2 | J8: 7.8 | K8: =I8/(E8+J8) -> 0.045925926 | L8: 7.4 | M8: 6 | N8: =L8/(E8+M8) -> 0.055555556 | O8: 14.8 | P8: 32.6 | Q8: =O8/(E8+P8) -> 0.09261577 | R8: 42.2 | S8: =R8/E8 -> 0.33176101 | T8: 5.6 | U8: =T8/R8 -> 0.13270142 | V8: 4.2 | W8: 0 | X8: =V8/(E8+W8) -> 0.033018868 | Y8: 18.4 | Z8: 4.8 | AA8: =Y8/E8 -> 0.14465409
A9: 2025-7/7~7/11 | B9: 印尼 | D9: 75 | E9: 108 | F9: 73.6 | G9: =F9/E9 -> 0.68148148 | H9: =(I9+L9+O9+R9+T9+V9+Y9)/F9 -> 1.8722826 | I9: 7.8 | J9: 10.8 | K9: =I9/(E9+J9) -> 0.065656566 | L9: 17.8 | M9: 10.4 | N9: =L9/(E9+M9) -> 0.15033784 | O9: 15.2 | P9: 27.4 | Q9: =O9/(E9+P9) -> 0.11225997 | R9: 51.8 | S9: =R9/E9 -> 0.47962963 | T9: 14.8 | U9: =T9/R9 -> 0.28571429 | V9: 11 | W9: 0 | X9: =V9/(E9+W9) -> 0.10185185 | Y9: 19.4 | Z9: 4.8 | AA9: =Y9/E9 -> 0.17962963
A10: 2025-7/7~7/11 | B10: 总计 | D10: =D8+D9 -> 171.2 | E10: =E8+E9 -> 235.2 | F10: =F8+F9 -> 134.4 | G10: =F10/E10 -> 0.57142857 | H10: =(I10+L10+O10+R10+T10+V10+Y10)/F10 -> 1.7604167 | I10: =I8+I9 -> 14 | J10: =J8+J9 -> 18.6 | K10: =I10/(E10+J10) -> 0.055161545 | L10: =L8+L9 -> 25.2 | M10: =M8+M9 -> 16.4 | N10: =L10/(E10+M10) -> 0.10015898 | O10: =O8+O9 -> 30 | P10: =P8+P9 -> 60 | Q10: =O10/(E10+P10) -> 0.10162602 | R10: =R8+R9 -> 94 | S10: =R10/E10 -> 0.39965986 | T10: =T8+T9 -> 20.4 | U10: =T10/R10 -> 0.21702128 | V10: =V8+V9 -> 15.2 | W10: =W8+W9 -> 0 | X10: =V10/(E10+W10) -> 0.06462585 | Y10: =Y8+Y9 -> 37.8 | Z10: =Z8+Z9 -> 9.6 | AA10: =Y10/(E10+Z10) -> 0.15441176
A11: 2025-7/14~7/18 | B11: 印度/巴基斯坦 | D11: 114.8 | E11: 141 | F11: 79.8 | G11: =F11/E11 -> 0.56595745 | H11: =(I11+L11+O11+R11+T11+V11+Y11)/F11 -> 1.5714286 | I11: 9.6 | J11: 10.4 | K11: =I11/(E11+J11) -> 0.06340819 | L11: 8.4 | M11: 6.8 | N11: =L11/(E11+M11) -> 0.056833559 | O11: 20.6 | P11: 41.4 | Q11: =O11/(E11+P11) -> 0.1129386 | R11: 50.8 | S11: =R11/E11 -> 0.36028369 | T11: 9 | U11: =T11/R11 -> 0.17716535 | V11: 5 | W11: 0.2 | X11: =V11/(E11+W11) -> 0.035410765 | Y11: 22 | Z11: 4.2 | AA11: =Y11/E11 -> 0.15602837
A12: 2025-7/14~7/18 | B12: 印尼 | D12: 102 | E12: 132.4 | F12: 86.6 | G12: =F12/E12 -> 0.65407855 | H12: =(I12+L12+O12+R12+T12+V12+Y12)/F12 -> 1.7921478 | I12: 8.2 | J12: 13.4 | K12: =I12/(E12+J12) -> 0.056241427 | L12: 19.8 | M12: 12.8 | N12: =L12/(E12+M12) -> 0.13636364 | O12: 14.4 | P12: 37.2 | Q12: =O12/(E12+P12) -> 0.08490566 | R12: 60.6 | S12: =R12/E12 -> 0.45770393 | T12: 16.4 | U12: =T12/R12 -> 0.27062706 | V12: 12.4 | W12: 0 | X12: =V12/(E12+W12) -> 0.093655589 | Y12: 23.4 | Z12: 5.4 | AA12: =Y12/E12 -> 0.17673716
A13: 2025-7/14~7/18 | B13: 总计 | D13: =D11+D12 -> 216.8 | E13: =E11+E12 -> 273.4 | F13: =F11+F12 -> 166.4 | G13: =F13/E13 -> 0.60863204 | H13: =(I13+L13+O13+R13+T13+V13+Y13)/F13 -> 1.6862981 | I13: =I11+I12 -> 17.8 | J13: =J11+J12 -> 23.8 | K13: =I13/(E13+J13) -> 0.059892328 | L13: =L11+L12 -> 28.2 | M13: =M11+M12 -> 19.6 | N13: =L13/(E13+M13) -> 0.096245734 | O13: =O11+O12 -> 35 | P13: =P11+P12 -> 78.6 | Q13: =O13/(E13+P13) -> 0.099431818 | R13: =R11+R12 -> 111.4 | S13: =R13/E13 -> 0.40746159 | T13: =T11+T12 -> 25.4 | U13: =T13/R13 -> 0.22800718 | V13: =V11+V12 -> 17.4 | W13: =W11+W12 -> 0.2 | X13: =V13/(E13+W13) -> 0.063596491 | Y13: =Y11+Y12 -> 45.4 | Z13: =Z11+Z12 -> 9.6 | AA13: =Y13/(E13+Z13) -> 0.16042403
A14: 2025-7/21~7/25 | B14: 印度/巴基斯坦 | D14: 84.4 | E14: 134.8 | F14: 70.6 | G14: =F14/E14 -> 0.52373887 | H14: =(I14+L14+O14+R14+T14+V14+Y14)/F14 -> 1.5750708 | I14: 8 | J14: 10.6 | K14: =I14/(E14+J14) -> 0.055020633 | L14: 5.8 | M14: 4.6 | N14: =L14/(E14+M14) -> 0.041606887 | O14: 14.4 | P14: 33.4 | Q14: =O14/(E14+P14) -> 0.085612366 | R14: 46 | S14: =R14/E14 -> 0.34124629 | T14: 4.4 | U14: =T14/R14 -> 0.095652174 | V14: 6.6 | W14: 0 | X14: =V14/(E14+W14) -> 0.048961424 | Y14: 26 | Z14: 3.6 | AA14: =Y14/E14 -> 0.19287834
A15: 2025-7/21~7/25 | B15: 印尼 | D15: 98.6 | E15: 127.4 | F15: 82 | G15: =F15/E15 -> 0.64364207 | H15: =(I15+L15+O15+R15+T15+V15+Y15)/F15 -> 1.7365854 | I15: 9.2 | J15: 12 | K15: =I15/(E15+J15) -> 0.065997131 | L15: 17.6 | M15: 12.8 | N15: =L15/(E15+M15) -> 0.12553495 | O15: 13.6 | P15: 31.6 | Q15: =O15/(E15+P15) -> 0.085534591 | R15: 57.4 | S15: =R15/E15 -> 0.45054945 | T15: 17 | U15: =T15/R15 -> 0.29616725 | V15: 8.6 | W15: 0.2 | X15: =V15/(E15+W15) -> 0.067398119 | Y15: 19 | Z15: 3 | AA15: =Y15/E15 -> 0.14913658
A16: 2025-7/21~7/25 | B16: 总计 | D16: =D14+D15 -> 183 | E16: =E14+E15 -> 262.2 | F16: =F14+F15 -> 152.6 | G16: =F16/E16 -> 0.58199847 | H16: =(I16+L16+O16+R16+T16+V16+Y16)/F16 -> 1.6618611 | I16: =I14+I15 -> 17.2 | J16: =J14+J15 -> 22.6 | K16: =I16/(E16+J16) -> 0.060393258 | L16: =L14+L15 -> 23.4 | M16: =M14+M15 -> 17.4 | N16: =L16/(E16+M16) -> 0.083690987 | O16: =O14+O15 -> 28 | P16: =P14+P15 -> 65 | Q16: =O16/(E16+P16) -> 0.085574572 | R16: =R14+R15 -> 103.4 | S16: =R16/E16 -> 0.39435545 | T16: =T14+T15 -> 21.4 | U16: =T16/R16 -> 0.20696325 | V16: =V14+V15 -> 15.2 | W16: =W14+W15 -> 0.2 | X16: =V16/(E16+W16) -> 0.057926829 | Y16: =Y14+Y15 -> 45 | Z16: =Z14+Z15 -> 6.6 | AA16: =Y16/(E16+Z16) -> 0.16741071
A17: 2025-7/28~8/1 | B17: 印度/巴基斯坦 | D17: 109.2 | E17: 152.4 | F17: 75 | G17: =F17/E17 -> 0.49212598 | H17: =(I17+L17+O17+R17+T17+V17+Y17)/F17 -> 1.6106667 | I17: 8.2 | J17: 9.8 | K17: =I17/(E17+J17) -> 0.050554871 | L17: 8.4 | M17: 6.8 | N17: =L17/(E17+M17) -> 0.052763819 | O17: 20.2 | P17: 40 | Q17: =O17/(E17+P17) -> 0.1049896 | R17: 48 | S17: =R17/E17 -> 0.31496063 | T17: 6.2 | U17: =T17/R17 -> 0.12916667 | V17: 6.2 | W17: 0 | X17: =V17/(E17+W17) -> 0.040682415 | Y17: 23.6 | Z17: 4.4 | AA17: =Y17/E17 -> 0.15485564
A18: 2025-7/28~8/1 | B18: 印尼 | D18: 107.4 | E18: 132.8 | F18: 86.6 | G18: =F18/E18 -> 0.65210843 | H18: =(I18+L18+O18+R18+T18+V18+Y18)/F18 -> 1.6812933 | I18: 8.2 | J18: 11.8 | K18: =I18/(E18+J18) -> 0.05670816 | L18: 20.8 | M18: 13.6 | N18: =L18/(E18+M18) -> 0.1420765 | O18: 12 | P18: 33.4 | Q18: =O18/(E18+P18) -> 0.072202166 | R18: 57.8 | S18: =R18/E18 -> 0.43524096 | T18: 18.2 | U18: =T18/R18 -> 0.31487889 | V18: 7.2 | W18: 0.2 | X18: =V18/(E18+W18) -> 0.054135338 | Y18: 21.4 | Z18: 4.6 | AA18: =Y18/E18 -> 0.16114458
A19: 2025-7/28~8/1 | B19: 总计 | D19: =D17+D18 -> 216.6 | E19: =E17+E18 -> 285.2 | F19: =F17+F18 -> 161.6 | G19: =F19/E19 -> 0.56661992 | H19: =(I19+L19+O19+R19+T19+V19+Y19)/F19 -> 1.6485149 | I19: =I17+I18 -> 16.4 | J19: =J17+J18 -> 21.6 | K19: =I19/(E19+J19) -> 0.05345502 | L19: =L17+L18 -> 29.2 | M19: =M17+M18 -> 20.4 | N19: =L19/(E19+M19) -> 0.095549738 | O19: =O17+O18 -> 32.2 | P19: =P17+P18 -> 73.4 | Q19: =O19/(E19+P19) -> 0.089793642 | R19: =R17+R18 -> 105.8 | S19: =R19/E19 -> 0.37096774 | T19: =T17+T18 -> 24.4 | U19: =T19/R19 -> 0.23062382 | V19: =V17+V18 -> 13.4 | W19: =W17+W18 -> 0.2 | X19: =V19/(E19+W19) -> 0.046951647 | Y19: =Y17+Y18 -> 45 | Z19: =Z17+Z18 -> 9 | AA19: =Y19/(E19+Z19) -> 0.15295717
A20: 2025-8/4~8/8 | B20: 印度/巴基斯坦 | D20: 104.6 | E20: 135 | F20: 70 | G20: =F20/E20 -> 0.51851852 | H20: =(I20+L20+O20+R20+T20+V20+Y20)/F20 -> 1.6142857 | I20: 8.2 | J20: 6.4 | K20: =I20/(E20+J20) -> 0.057991513 | L20: 9 | M20: 7 | N20: =L20/(E20+M20) -> 0.063380282 | O20: 16.4 | P20: 35.2 | Q20: =O20/(E20+P20) -> 0.096357227 | R20: 45 | S20: =R20/E20 -> 0.33333333 | T20: 4.8 | U20: =T20/R20 -> 0.10666667 | V20: 6.2 | W20: 0.2 | X20: =V20/(E20+W20) -> 0.045857988 | Y20: 23.4 | Z20: 3.4 | AA20: =Y20/E20 -> 0.17333333
A21: 2025-8/4~8/8 | B21: 印尼 | D21: 117 | E21: 124.2 | F21: 85.8 | G21: =F21/E21 -> 0.69082126 | H21: =(I21+L21+O21+R21+T21+V21+Y21)/F21 -> 1.7948718 | I21: 9 | J21: 10.4 | K21: =I21/(E21+J21) -> 0.066864785 | L21: 20.2 | M21: 14.4 | N21: =L21/(E21+M21) -> 0.14574315 | O21: 14.2 | P21: 34 | Q21: =O21/(E21+P21) -> 0.089759798 | R21: 62.6 | S21: =R21/E21 -> 0.50402576 | T21: 14.6 | U21: =T21/R21 -> 0.23322684 | V21: 13 | W21: 0 | X21: =V21/(E21+W21) -> 0.10466989 | Y21: 20.4 | Z21: 4.2 | AA21: =Y21/E21 -> 0.16425121
A22: 2025-8/4~8/8 | B22: 总计 | D22: =D20+D21 -> 221.6 | E22: =E20+E21 -> 259.2 | F22: =F20+F21 -> 155.8 | G22: =F22/E22 -> 0.60108025 | H22: =(I22+L22+O22+R22+T22+V22+Y22)/F22 -> 1.7137356 | I22: =I20+I21 -> 17.2 | J22: =J20+J21 -> 16.8 | K22: =I22/(E22+J22) -> 0.062318841 | L22: =L20+L21 -> 29.2 | M22: =M20+M21 -> 21.4 | N22: =L22/(E22+M22) -> 0.10406272 | O22: =O20+O21 -> 30.6 | P22: =P20+P21 -> 69.2 | Q22: =O22/(E22+P22) -> 0.09317905 | R22: =R20+R21 -> 107.6 | S22: =R22/E22 -> 0.41512346 | T22: =T20+T21 -> 19.4 | U22: =T22/R22 -> 0.1802974 | V22: =V20+V21 -> 19.2 | W22: =W20+W21 -> 0.2 | X22: =V22/(E22+W22) -> 0.074016962 | Y22: =Y20+Y21 -> 43.8 | Z22: =Z20+Z21 -> 7.6 | AA22: =Y22/(E22+Z22) -> 0.16416792
A23: 2025-8/11~8/15 | B23: 印度/巴基斯坦 | D23: 122.8 | E23: 116.6 | F23: 63 | G23: =F23/E23 -> 0.54030875 | H23: =(I23+L23+O23+R23+T23+V23+Y23)/F23 -> 1.7460317 | I23: 5 | J23: 8 | K23: =I23/(E23+J23) -> 0.040128411 | L23: 6 | M23: 4.4 | N23: =L23/(E23+M23) -> 0.049586777 | O23: 19.8 | P23: 38.4 | Q23: =O23/(E23+P23) -> 0.12774194 | R23: 46.2 | S23: =R23/E23 -> 0.39622642 | T23: 6.2 | U23: =T23/R23 -> 0.13419913 | V23: 6.4 | W23: 0 | X23: =V23/(E23+W23) -> 0.054888508 | Y23: 20.4 | Z23: 4 | AA23: =Y23/E23 -> 0.17495712
A24: 2025-8/11~8/15 | B24: 印尼 | D24: 98 | E24: 114.2 | F24: 81.6 | G24: =F24/E24 -> 0.7145359 | H24: =(I24+L24+O24+R24+T24+V24+Y24)/F24 -> 1.7303922 | I24: 4.8 | J24: 9 | K24: =I24/(E24+J24) -> 0.038961039 | L24: 25.4 | M24: 14.4 | N24: =L24/(E24+M24) -> 0.19751166 | O24: 10.8 | P24: 32.8 | Q24: =O24/(E24+P24) -> 0.073469388 | R24: 53 | S24: =R24/E24 -> 0.46409807 | T24: 13.6 | U24: =T24/R24 -> 0.25660377 | V24: 13.4 | W24: 0.2 | X24: =V24/(E24+W24) -> 0.11713287 | Y24: 20.2 | Z24: 3 | AA24: =Y24/E24 -> 0.17688266
A25: 2025-8/11~8/15 | B25: 总计 | D25: =D23+D24 -> 220.8 | E25: =E23+E24 -> 230.8 | F25: =F23+F24 -> 144.6 | G25: =F25/E25 -> 0.62651646 | H25: =(I25+L25+O25+R25+T25+V25+Y25)/F25 -> 1.7372061 | I25: =I23+I24 -> 9.8 | J25: =J23+J24 -> 17 | K25: =I25/(E25+J25) -> 0.039548023 | L25: =L23+L24 -> 31.4 | M25: =M23+M24 -> 18.8 | N25: =L25/(E25+M25) -> 0.12580128 | O25: =O23+O24 -> 30.6 | P25: =P23+P24 -> 71.2 | Q25: =O25/(E25+P25) -> 0.1013245 | R25: =R23+R24 -> 99.2 | S25: =R25/E25 -> 0.42980936 | T25: =T23+T24 -> 19.8 | U25: =T25/R25 -> 0.19959677 | V25: =V23+V24 -> 19.8 | W25: =W23+W24 -> 0.2 | X25: =V25/(E25+W25) -> 0.085714286 | Y25: =Y23+Y24 -> 40.6 | Z25: =Z23+Z24 -> 7 | AA25: =Y25/(E25+Z25) -> 0.17073171
A26: 2025-8/18~8/22 | B26: 印度/巴基斯坦 | D26: 109.2 | E26: 137.8 | F26: 74.4 | G26: =F26/E26 -> 0.53991292 | H26: =(I26+L26+O26+R26+T26+V26+Y26)/F26 -> 1.6102151 | I26: 6.4 | J26: 9.6 | K26: =I26/(E26+J26) -> 0.043419267 | L26: 9.8 | M26: 7.6 | N26: =L26/(E26+M26) -> 0.067400275 | O26: 15.4 | P26: 37.6 | Q26: =O26/(E26+P26) -> 0.087799316 | R26: 48 | S26: =R26/E26 -> 0.34833091 | T26: 7.8 | U26: =T26/R26 -> 0.1625 | V26: 4.4 | W26: 0 | X26: =V26/(E26+W26) -> 0.031930334 | Y26: 28 | Z26: 5.2 | AA26: =Y26/E26 -> 0.20319303
A27: 2025-8/18~8/22 | B27: 印尼 | D27: 105.8 | E27: 105.2 | F27: 73.6 | G27: =F27/E27 -> 0.69961977 | H27: =(I27+L27+O27+R27+T27+V27+Y27)/F27 -> 1.6956522 | I27: 6.4 | J27: 8.2 | K27: =I27/(E27+J27) -> 0.05643739 | L27: 19.6 | M27: 13.4 | N27: =L27/(E27+M27) -> 0.16526138 | O27: 11.6 | P27: 29.6 | Q27: =O27/(E27+P27) -> 0.086053412 | R27: 50.8 | S27: =R27/E27 -> 0.48288973 | T27: 11.6 | U27: =T27/R27 -> 0.22834646 | V27: 8 | W27: 0 | X27: =V27/(E27+W27) -> 0.076045627 | Y27: 16.8 | Z27: 3.2 | AA27: =Y27/E27 -> 0.15969582
A28: 2025-8/18~8/22 | B28: 总计 | D28: =D26+D27 -> 215 | E28: =E26+E27 -> 243 | F28: =F26+F27 -> 148 | G28: =F28/E28 -> 0.6090535 | H28: =(I28+L28+O28+R28+T28+V28+Y28)/F28 -> 1.6527027 | I28: =I26+I27 -> 12.8 | J28: =J26+J27 -> 17.8 | K28: =I28/(E28+J28) -> 0.049079755 | L28: =L26+L27 -> 29.4 | M28: =M26+M27 -> 21 | N28: =L28/(E28+M28) -> 0.11136364 | O28: =O26+O27 -> 27 | P28: =P26+P27 -> 67.2 | Q28: =O28/(E28+P28) -> 0.087040619 | R28: =R26+R27 -> 98.8 | S28: =R28/E28 -> 0.40658436 | T28: =T26+T27 -> 19.4 | U28: =T28/R28 -> 0.19635628 | V28: =V26+V27 -> 12.4 | W28: =W26+W27 -> 0 | X28: =V28/(E28+W28) -> 0.051028807 | Y28: =Y26+Y27 -> 44.8 | Z28: =Z26+Z27 -> 8.4 | AA28: =Y28/(E28+Z28) -> 0.17820207
A29: 2025-8/25~8/29 | B29: 印度/巴基斯坦 | D29: 121.4 | E29: 131.4 | F29: 77.2 | G29: =F29/E29 -> 0.58751903 | H29: =(I29+L29+O29+R29+T29+V29+Y29)/F29 -> 1.6036269 | I29: 7.4 | J29: 7.8 | K29: =I29/(E29+J29) -> 0.05316092 | L29: 9.8 | M29: 7.4 | N29: =L29/(E29+M29) -> 0.070605187 | O29: 20 | P29: 45.8 | Q29: =O29/(E29+P29) -> 0.11286682 | R29: 52.6 | S29: =R29/E29 -> 0.40030441 | T29: 7.4 | U29: =T29/R29 -> 0.14068441 | V29: 5.4 | W29: 0 | X29: =V29/(E29+W29) -> 0.04109589 | Y29: 21.2 | Z29: 3.2 | AA29: =Y29/E29 -> 0.16133942
A30: 2025-8/25~8/29 | B30: 印尼 | D30: 116.8 | E30: 119.2 | F30: 80.2 | G30: =F30/E30 -> 0.67281879 | H30: =(I30+L30+O30+R30+T30+V30+Y30)/F30 -> 1.8054863 | I30: 5.4 | J30: 9 | K30: =I30/(E30+J30) -> 0.042121685 | L30: 21.6 | M30: 14.2 | N30: =L30/(E30+M30) -> 0.16191904 | O30: 10.2 | P30: 31.4 | Q30: =O30/(E30+P30) -> 0.067729084 | R30: 55.6 | S30: =R30/E30 -> 0.46644295 | T30: 13.6 | U30: =T30/R30 -> 0.24460432 | V30: 15 | W30: 0 | X30: =V30/(E30+W30) -> 0.12583893 | Y30: 23.4 | Z30: 4 | AA30: =Y30/E30 -> 0.19630872
A31: 2025-8/25~8/29 | B31: 总计 | D31: =D29+D30 -> 238.2 | E31: =E29+E30 -> 250.6 | F31: =F29+F30 -> 157.4 | G31: =F31/E31 -> 0.62809258 | H31: =(I31+L31+O31+R31+T31+V31+Y31)/F31 -> 1.7064803 | I31: =I29+I30 -> 12.8 | J31: =J29+J30 -> 16.8 | K31: =I31/(E31+J31) -> 0.047868362 | L31: =L29+L30 -> 31.4 | M31: =M29+M30 -> 21.6 | N31: =L31/(E31+M31) -> 0.11535636 | O31: =O29+O30 -> 30.2 | P31: =P29+P30 -> 77.2 | Q31: =O31/(E31+P31) -> 0.092129347 | R31: =R29+R30 -> 108.2 | S31: =R31/E31 -> 0.43176377 | T31: =T29+T30 -> 21 | U31: =T31/R31 -> 0.19408503 | V31: =V29+V30 -> 20.4 | W31: =W29+W30 -> 0 | X31: =V31/(E31+W31) -> 0.081404629 | Y31: =Y29+Y30 -> 44.6 | Z31: =Z29+Z30 -> 7.2 | AA31: =Y31/(E31+Z31) -> 0.17300233
A32: 2025-9/1~9/5 | B32: 印度/巴基斯坦 | D32: 110.2 | E32: 134.8 | F32: 70.6 | G32: =F32/E32 -> 0.52373887 | H32: =(I32+L32+O32+R32+T32+V32+Y32)/F32 -> 1.5977337 | I32: 5.2 | J32: 8.2 | K32: =I32/(E32+J32) -> 0.036363636 | L32: 8.2 | M32: 5.8 | N32: =L32/(E32+M32) -> 0.058321479 | O32: 20.2 | P32: 39.4 | Q32: =O32/(E32+P32) -> 0.11595867 | R32: 47.8 | S32: =R32/E32 -> 0.35459941 | T32: 7 | U32: =T32/R32 -> 0.14644351 | V32: 4.8 | W32: 0 | X32: =V32/(E32+W32) -> 0.035608309 | Y32: 19.6 | Z32: 3.2 | AA32: =Y32/E32 -> 0.14540059
A33: 2025-9/1~9/5 | B33: 印尼 | D33: 89.2 | E33: 124.8 | F33: 83.4 | G33: =F33/E33 -> 0.66826923 | H33: =(I33+L33+O33+R33+T33+V33+Y33)/F33 -> 1.7482014 | I33: 6 | J33: 10.6 | K33: =I33/(E33+J33) -> 0.044313146 | L33: 25.8 | M33: 19.2 | N33: =L33/(E33+M33) -> 0.17916667 | O33: 13.6 | P33: 31 | Q33: =O33/(E33+P33) -> 0.087291399 | R33: 53.8 | S33: =R33/E33 -> 0.43108974 | T33: 15.8 | U33: =T33/R33 -> 0.2936803 | V33: 11.4 | W33: 0.4 | X33: =V33/(E33+W33) -> 0.091054313 | Y33: 19.4 | Z33: 3 | AA33: =Y33/E33 -> 0.15544872
A34: 2025-9/1~9/5 | B34: 总计 | D34: =D32+D33 -> 199.4 | E34: =E32+E33 -> 259.6 | F34: =F32+F33 -> 154 | G34: =F34/E34 -> 0.59322034 | H34: =(I34+L34+O34+R34+T34+V34+Y34)/F34 -> 1.6792208 | I34: =I32+I33 -> 11.2 | J34: =J32+J33 -> 18.8 | K34: =I34/(E34+J34) -> 0.040229885 | L34: =L32+L33 -> 34 | M34: =M32+M33 -> 25 | N34: =L34/(E34+M34) -> 0.11946592 | O34: =O32+O33 -> 33.8 | P34: =P32+P33 -> 70.4 | Q34: =O34/(E34+P34) -> 0.10242424 | R34: =R32+R33 -> 101.6 | S34: =R34/E34 -> 0.39137134 | T34: =T32+T33 -> 22.8 | U34: =T34/R34 -> 0.22440945 | V34: =V32+V33 -> 16.2 | W34: =W32+W33 -> 0.4 | X34: =V34/(E34+W34) -> 0.062307692 | Y34: =Y32+Y33 -> 39 | Z34: =Z32+Z33 -> 6.2 | AA34: =Y34/(E34+Z34) -> 0.14672686
A35: 2025-9/8~9/12 | B35: 印度/巴基斯坦 | D35: 128.4 | E35: 176.4 | F35: 101.4 | G35: =F35/E35 -> 0.57482993 | H35: =(I35+L35+O35+R35+T35+V35+Y35)/F35 -> 1.556213 | I35: 11.4 | J35: 12.2 | K35: =I35/(E35+J35) -> 0.060445387 | L35: 11 | M35: 9 | N35: =L35/(E35+M35) -> 0.059331176 | O35: 28 | P35: 56.2 | Q35: =O35/(E35+P35) -> 0.12037833 | R35: 66.2 | S35: =R35/E35 -> 0.37528345 | T35: 7.6 | U35: =T35/R35 -> 0.11480363 | V35: 4.6 | W35: 0 | X35: =V35/(E35+W35) -> 0.026077098 | Y35: 29 | Z35: 4.6 | AA35: =Y35/E35 -> 0.16439909
A36: 2025-9/8~9/12 | B36: 印尼 | D36: 129.6 | E36: 133.8 | F36: 94.4 | G36: =F36/E36 -> 0.70553064 | H36: =(I36+L36+O36+R36+T36+V36+Y36)/F36 -> 1.7881356 | I36: 9.4 | J36: 11.8 | K36: =I36/(E36+J36) -> 0.06456044 | L36: 31 | M36: 22.6 | N36: =L36/(E36+M36) -> 0.19820972 | O36: 14.8 | P36: 36.6 | Q36: =O36/(E36+P36) -> 0.08685446 | R36: 59.4 | S36: =R36/E36 -> 0.44394619 | T36: 18.2 | U36: =T36/R36 -> 0.30639731 | V36: 11 | W36: 0.4 | X36: =V36/(E36+W36) -> 0.081967213 | Y36: 25 | Z36: 4 | AA36: =Y36/E36 -> 0.18684604
A37: 2025-9/8~9/12 | B37: 总计 | D37: =D35+D36 -> 258 | E37: =E35+E36 -> 310.2 | F37: =F35+F36 -> 195.8 | G37: =F37/E37 -> 0.63120567 | H37: =(I37+L37+O37+R37+T37+V37+Y37)/F37 -> 1.6680286 | I37: =I35+I36 -> 20.8 | J37: =J35+J36 -> 24 | K37: =I37/(E37+J37) -> 0.062238181 | L37: =L35+L36 -> 42 | M37: =M35+M36 -> 31.6 | N37: =L37/(E37+M37) -> 0.12287888 | O37: =O35+O36 -> 42.8 | P37: =P35+P36 -> 92.8 | Q37: =O37/(E37+P37) -> 0.10620347 | R37: =R35+R36 -> 125.6 | S37: =R37/E37 -> 0.40490006 | T37: =T35+T36 -> 25.8 | U37: =T37/R37 -> 0.20541401 | V37: =V35+V36 -> 15.6 | W37: =W35+W36 -> 0.4 | X37: =V37/(E37+W37) -> 0.05022537 | Y37: =Y35+Y36 -> 54 | Z37: =Z35+Z36 -> 8.6 | AA37: =Y37/(E37+Z37) -> 0.16938519
A38: 2025-9/15~9/19 | B38: 印度/巴基斯坦 | D38: 171 | E38: 182.2 | F38: 105 | G38: =F38/E38 -> 0.57628979 | H38: =(I38+L38+O38+R38+T38+V38+Y38)/F38 -> 1.6133333 | I38: 10 | J38: 14 | K38: =I38/(E38+J38) -> 0.0509684 | L38: 14.6 | M38: 11.4 | N38: =L38/(E38+M38) -> 0.075413223 | O38: 26.4 | P38: 57 | Q38: =O38/(E38+P38) -> 0.11036789 | R38: 70 | S38: =R38/E38 -> 0.38419319 | T38: 9.2 | U38: =T38/R38 -> 0.13142857 | V38: 7.6 | W38: 0 | X38: =V38/(E38+W38) -> 0.041712404 | Y38: 31.6 | Z38: 7.4 | AA38: =Y38/E38 -> 0.17343578
A39: 2025-9/15~9/19 | B39: 印尼 | D39: 146.4 | E39: 167.4 | F39: 116.4 | G39: =F39/E39 -> 0.6953405 | H39: =(I39+L39+O39+R39+T39+V39+Y39)/F39 -> 1.8591065 | I39: 11.2 | J39: 16.2 | K39: =I39/(E39+J39) -> 0.061002179 | L39: 33.2 | M39: 24.8 | N39: =L39/(E39+M39) -> 0.17273673 | O39: 16 | P39: 42.8 | Q39: =O39/(E39+P39) -> 0.076117983 | R39: 79 | S39: =R39/E39 -> 0.47192354 | T39: 21.2 | U39: =T39/R39 -> 0.26835443 | V39: 14.4 | W39: 0 | X39: =V39/(E39+W39) -> 0.086021505 | Y39: 41.4 | Z39: 5.6 | AA39: =Y39/E39 -> 0.24731183
A40: 2025-9/15~9/19 | B40: 总计 | D40: =D38+D39 -> 317.4 | E40: =E38+E39 -> 349.6 | F40: =F38+F39 -> 221.4 | G40: =F40/E40 -> 0.63329519 | H40: =(I40+L40+O40+R40+T40+V40+Y40)/F40 -> 1.7425474 | I40: =I38+I39 -> 21.2 | J40: =J38+J39 -> 30.2 | K40: =I40/(E40+J40) -> 0.055818852 | L40: =L38+L39 -> 47.8 | M40: =M38+M39 -> 36.2 | N40: =L40/(E40+M40) -> 0.12389839 | O40: =O38+O39 -> 42.4 | P40: =P38+P39 -> 99.8 | Q40: =O40/(E40+P40) -> 0.09434802 | R40: =R38+R39 -> 149 | S40: =R40/E40 -> 0.42620137 | T40: =T38+T39 -> 30.4 | U40: =T40/R40 -> 0.20402685 | V40: =V38+V39 -> 22 | W40: =W38+W39 -> 0 | X40: =V40/(E40+W40) -> 0.062929062 | Y40: =Y38+Y39 -> 73 | Z40: =Z38+Z39 -> 13 | AA40: =Y40/(E40+Z40) -> 0.20132377
A41: 2025-9/22~9/26 | B41: 印度/巴基斯坦 | D41: 146 | E41: 197.8 | F41: 112 | G41: =F41/E41 -> 0.56622851 | H41: =(I41+L41+O41+R41+T41+V41+Y41)/F41 -> 1.6107143 | I41: 10 | J41: 14.2 | K41: =I41/(E41+J41) -> 0.047169811 | L41: 11.8 | M41: 9.6 | N41: =L41/(E41+M41) -> 0.056894889 | O41: 32.8 | P41: 63 | Q41: =O41/(E41+P41) -> 0.12576687 | R41: 76.2 | S41: =R41/E41 -> 0.38523761 | T41: 11.2 | U41: =T41/R41 -> 0.14698163 | V41: 8 | W41: 0.2 | X41: =V41/(E41+W41) -> 0.04040404 | Y41: 30.4 | Z41: 7.4 | AA41: =Y41/E41 -> 0.1536906
...

Sheet WEB来源数据
C1: BI | D1: BI | G1: GSC | H1: Ahref | I1: GSC
A2: 周数 | B2: 地区 | C2: 自然北极星 | D2: 自然uv | E2: google自然 UV | F2: AI UV | G2: SEO自然UV | H2: google top3 | I2: google自然曝光 | J2: google点击率
A3: 2025-6/30~7/4 | B3: 印度/巴基斯坦 | C3: 256.1 | D3: 1061 | E3: 778.8 | F3: 0 | H3: 372
A4: 2025-6/30~7/4 | B4: 印尼 | C4: 240.6 | D4: 834.4 | E4: 592.6 | F4: 0.2 | H4: 141
A5: 2025-6/30~7/4 | B5: 总计 | C5: =C3+C4 -> 496.7 | D5: =D3+D4 -> 1895.4 | E5: =E3+E4 -> 1371.4 | F5: =F3+F4 -> 0.2
A6: 2025-7/7~7/11 | B6: 印度/巴基斯坦 | C6: 264 | D6: 1097 | E6: 815.2 | F6: 0 | H6: 374
A7: 2025-7/7~7/11 | B7: 印尼 | C7: 226.6 | D7: 794.8 | E7: 557.4 | F7: 0.6 | H7: 146
A8: 2025-7/7~7/11 | B8: 总计 | C8: =C6+C7 -> 490.6 | D8: =D6+D7 -> 1891.8 | E8: =E6+E7 -> 1372.6 | F8: =F6+F7 -> 0.6
A9: 2025-7/14~7/18 | B9: 印度/巴基斯坦 | C9: 300.9 | D9: 1124 | E9: 842.4 | F9: 0.2 | H9: 376
A10: 2025-7/14~7/18 | B10: 印尼 | C10: 267 | D10: 836.6 | E10: 592.4 | F10: 0.2 | H10: 150
A11: 2025-7/14~7/18 | B11: 总计 | C11: =C9+C10 -> 567.9 | D11: =D9+D10 -> 1960.6 | E11: =E9+E10 -> 1434.8 | F11: =F9+F10 -> 0.4
A12: 2025-7/21~7/25 | B12: 印度/巴基斯坦 | C12: 291.3 | D12: 1191.6 | E12: 880.2 | F12: 0.6 | H12: 406
A13: 2025-7/21~7/25 | B13: 印尼 | C13: 248.2 | D13: 842.6 | E13: 610.6 | F13: 0.2 | H13: 155
A14: 2025-7/21~7/25 | B14: 总计 | C14: =C12+C13 -> 539.5 | D14: =D12+D13 -> 2034.2 | E14: =E12+E13 -> 1490.8 | F14: =F12+F13 -> 0.8
A15: 2025-7/28~8/1 | B15: 印度/巴基斯坦 | C15: 293.4 | D15: 1334.8 | E15: 907.6 | F15: 1 | H15: 417
A16: 2025-7/28~8/1 | B16: 印尼 | C16: 230.1 | D16: 911.4 | E16: 579.2 | F16: 0 | H16: 164
A17: 2025-7/28~8/1 | B17: 总计 | C17: =C15+C16 -> 523.5 | D17: =D15+D16 -> 2246.2 | E17: =E15+E16 -> 1486.8 | F17: =F15+F16 -> 1
A18: 2025-8/4~8/8 | B18: 印度/巴基斯坦 | C18: 291.3 | D18: 1143.8 | E18: 846.8 | F18: 0 | H18: 414
A19: 2025-8/4~8/8 | B19: 印尼 | C19: 240.4 | D19: 837.4 | E19: 583 | F19: 0 | H19: 164
A20: 2025-8/4~8/8 | B20: 总计 | C20: =C18+C19 -> 531.7 | D20: =D18+D19 -> 1981.2 | E20: =E18+E19 -> 1429.8 | F20: =F18+F19 -> 0
A21: 2025-8/11~8/15 | B21: 印度/巴基斯坦 | C21: 268.2 | D21: 1138.6 | E21: 794 | F21: 0 | H21: 422
A22: 2025-8/11~8/15 | B22: 印尼 | C22: 221.4 | D22: 907.6 | E22: 571.6 | F22: 0 | H22: 174
A23: 2025-8/11~8/15 | B23: 总计 | C23: =C21+C22 -> 489.6 | D23: =D21+D22 -> 2046.2 | E23: =E21+E22 -> 1365.6 | F23: =F21+F22 -> 0
A24: 2025-8/18~8/22 | B24: 印度/巴基斯坦 | C24: 277.6 | D24: 1056.6 | E24: 759.8 | F24: 0.4 | H24: 401
A25: 2025-8/18~8/22 | B25: 印尼 | C25: 231.2 | D25: 903 | E25: 551 | F25: 0 | H25: 183
A26: 2025-8/18~8/22 | B26: 总计 | C26: =C24+C25 -> 508.8 | D26: =D24+D25 -> 1959.6 | E26: =E24+E25 -> 1310.8 | F26: =F24+F25 -> 0.4
A27: 2025-8/25~8/29 | B27: 印度/巴基斯坦 | C27: 316.7 | D27: 1217.8 | E27: 904.6 | F27: 0.4 | H27: 383
A28: 2025-8/25~8/29 | B28: 印尼 | C28: 225.9 | D28: 753.6 | E28: 539.6 | F28: 0.2 | H28: 187
A29: 2025-8/25~8/29 | B29: 总计 | C29: =C27+C28 -> 542.6 | D29: =D27+D28 -> 1971.4 | E29: =E27+E28 -> 1444.2 | F29: =F27+F28 -> 0.6
A30: 2025-9/1~9/5 | B30: 印度/巴基斯坦 | C30: 274 | D30: 1140.4 | E30: 777 | F30: 0.6 | H30: 359
A31: 2025-9/1~9/5 | B31: 印尼 | C31: 209.7 | D31: 726.2 | E31: 494.2 | F31: 0 | H31: 192
A32: 2025-9/1~9/5 | B32: 总计 | C32: =C30+C31 -> 483.7 | D32: =D30+D31 -> 1866.6 | E32: =E30+E31 -> 1271.2 | F32: =F30+F31 -> 0.6
A33: 2025-9/8~9/12 | B33: 印度/巴基斯坦 | C33: 310.1 | D33: 1204.8 | E33: 859.4 | F33: 0
A34: 2025-9/8~9/12 | B34: 印尼 | C34: 216.3 | D34: 754.8 | E34: 525.2 | F34: 0
A35: 2025-9/8~9/12 | B35: 总计 | C35: =C33+C34 -> 526.4 | D35: =D33+D34 -> 1959.6 | E35: =E33+E34 -> 1384.6 | F35: =F33+F34 -> 0
A36: 2025-9/15~9/19 | B36: 印度/巴基斯坦 | C36: 324.8 | D36: 1155.2 | E36: 813.8 | F36: 0.4
A37: 2025-9/15~9/19 | B37: 印尼 | C37: 241.3 | D37: 816 | E37: 568.8 | F37: 0.6
A38: 2025-9/15~9/19 | B38: 总计 | C38: =C36+C37 -> 566.1 | D38: =D36+D37 -> 1971.2 | E38: =E36+E37 -> 1382.6 | F38: =F36+F37 -> 1
A39: 2025-9/22~9/26 | B39: 印度/巴基斯坦 | C39: 266.3 | D39: 1100.2 | E39: 792.8 | F39: 1
A40: 2025-9/22~9/26 | B40: 印尼 | C40: 228.9 | D40: 838.6 | E40: 581.4 | F40: 0
...

Sheet WEB转化
E1: BI | F1: BI手动 | I1: BI | L1: BI | O1: BI | R1: BI | T1: BI | V1: BI | Y1: BI | AB1: BI | AE1: BI
I2: 商业内容 | L2: VPS活跃 | O2: 交易商搜索量 | R2: 交易商详情页 | T2: 交易商详情页外跳 | V2: 曝光内容 | Y2: 新闻内容 | AB2: 排行榜 | AE2: 评论
A3: 周数 | B3: 地区 | C3: 自然小BU | D3: 自然北极星 | E3: 自然uv | F3: 9点位去重人数 | G3: 9点位去重人数/UV | H3: 事件总数/9点位去重人数 | I3: 商业页面访问数 | J3: 商业频道首页访问数 | K3: 商业/（日活+频道首页） | L3: VPS页面访问数 | M3: VPS频道首页访问数 | N3: VPS/（日活+频道首页） | O3: 交易商搜索页面访问数 | P3: 所有搜索框访问数 | Q3: 搜索/（日活+频道首页） | R3: 交易商详情页面访问数 | S3: 交访/日活率 | T3: 外跳点击数 | U3: 外跳/交访率 | V3: 曝光页面访问数 | W3: 频道首页访问数 | X3: 曝光/（日活+频道首页） | Y3: 新闻页面访问数 | Z3: 新闻频道首页访问数 | AA3: 新闻/（日活+频道首页） | AB3: 排行榜页面访问数 | AC3: 排行榜频道首页访问数 | AD3: 排行榜/（日活+频道首页） | AE3: 评论页面访问数 | AF3: 评论/（交易商访问）
A4: 2025-6/30~7/4 | B4: 印度/巴基斯坦 | D4: 256.1 | E4: 1061 | F4: 882.6 | G4: =F4/E4 -> 0.83185674 | H4: =(I4+L4+O4+R4+T4+V4+Y4+AB4+AE4)/F4 -> 1.5293451 | I4: 32.6 | J4: 0.4 | K4: =I4/(E4+J4) -> 0.030714151 | L4: 3.6 | M4: 0 | N4: =L4/(E4+M4) -> 0.0033930254 | O4: 282.8 | P4: 282.8 | Q4: =O4/(E4+P4) -> 0.21044798 | R4: 721.2 | S4: =R4/E4 -> 0.6797361 | T4: 105.6 | U4: =T4/R4 -> 0.14642263 | V4: 9.6 | W4: 0 | X4: =V4/(E4+W4) -> 0.0090480679 | Y4: 101.2 | Z4: 1.4 | AA4: =Y4/(E4+Z4) -> 0.095256024 | AB4: 49 | AC4: 0 | AD4: =AB4/(E4+AC4) -> 0.046182846 | AE4: 44.2 | AF4: =AE4/R4 -> 0.061286744
A5: 2025-6/30~7/4 | B5: 印尼 | D5: 240.6 | E5: 834.4 | F5: 721.6 | G5: =F5/E5 -> 0.86481304 | H5: =(I5+L5+O5+R5+T5+V5+Y5+AB5+AE5)/F5 -> 1.6992794 | I5: 48.2 | J5: 0.4 | K5: =I5/(E5+J5) -> 0.05773838 | L5: 14.2 | M5: 0 | N5: =L5/(E5+M5) -> 0.017018217 | O5: 220.4 | P5: 220.4 | Q5: =O5/(E5+P5) -> 0.20894956 | R5: 533.2 | S5: =R5/E5 -> 0.63902205 | T5: 159.2 | U5: =T5/R5 -> 0.29857464 | V5: 16.2 | W5: 0 | X5: =V5/(E5+W5) -> 0.019415149 | Y5: 132.4 | Z5: 1.6 | AA5: =Y5/(E5+Z5) -> 0.15837321 | AB5: 66 | AC5: 0 | AD5: =AB5/(E5+AC5) -> 0.079098754 | AE5: 36.4 | AF5: =AE5/R5 -> 0.068267067
A6: 2025-6/30~7/4 | B6: 总计 | D6: =D4+D5 -> 496.7 | E6: =E4+E5 -> 1895.4 | F6: =F4+F5 -> 1604.2 | G6: =F6/E6 -> 0.84636488 | H6: =(I6+L6+O6+R6+T6+V6+Y6+AB6+AE6)/F6 -> 1.6057848 | I6: =I4+I5 -> 80.8 | J6: =J4+J5 -> 0.8 | K6: =I6/(E6+J6) -> 0.042611539 | L6: =L4+L5 -> 17.8 | N6: =L6/(E6+M6) -> 0.0093911575 | O6: =O4+O5 -> 503.2 | P6: =P4+P5 -> 503.2 | Q6: =O6/(E6+P6) -> 0.20978904 | R6: =R4+R5 -> 1254.4 | S6: =R6/E6 -> 0.66181281 | T6: =T4+T5 -> 264.8 | U6: =T6/R6 -> 0.21109694 | V6: =V4+V5 -> 25.8 | X6: =V6/(E6+W6) -> 0.013611903 | Y6: =Y4+Y5 -> 233.6 | Z6: =Z4+Z5 -> 3 | AA6: =Y6/(E6+Z6) -> 0.12305099 | AB6: =AB4+AB5 -> 115 | AD6: =AB6/(E6+AC6) -> 0.060673209 | AE6: =AE4+AE5 -> 80.6 | AF6: =AE6/R6 -> 0.064253827
A7: 2025-7/7~7/11 | B7: 印度/巴基斯坦 | D7: 264 | E7: 1097 | F7: 929.4 | G7: =F7/E7 -> 0.84721969 | H7: =(I7+L7+O7+R7+T7+V7+Y7+AB7+AE7)/F7 -> 1.5455132 | I7: 32.8 | J7: 0 | K7: =I7/(E7+J7) -> 0.029899727 | L7: 3.8 | M7: 0 | N7: =L7/(E7+M7) -> 0.0034639927 | O7: 312.6 | P7: 312.6 | Q7: =O7/(E7+P7) -> 0.22176504 | R7: 779.8 | S7: =R7/E7 -> 0.71084777 | T7: 106.2 | U7: =T7/R7 -> 0.13618877 | V7: 11 | W7: 0 | X7: =V7/(E7+W7) -> 0.010027347 | Y7: 84.8 | Z7: 2.2 | AA7: =Y7/(E7+Z7) -> 0.077147016 | AB7: 59.4 | AC7: 0 | AD7: =AB7/(E7+AC7) -> 0.054147675 | AE7: 46 | AF7: =AE7/R7 -> 0.058989484
A8: 2025-7/7~7/11 | B8: 印尼 | D8: 226.6 | E8: 794.8 | F8: 698.6 | G8: =F8/E8 -> 0.87896326 | H8: =(I8+L8+O8+R8+T8+V8+Y8+AB8+AE8)/F8 -> 1.7489264 | I8: 54.2 | J8: 0.4 | K8: =I8/(E8+J8) -> 0.068158954 | L8: 11.2 | M8: 0 | N8: =L8/(E8+M8) -> 0.014091595 | O8: 231.4 | P8: 231.4 | Q8: =O8/(E8+P8) -> 0.22549211 | R8: 513 | S8: =R8/E8 -> 0.6454454 | T8: 156 | U8: =T8/R8 -> 0.30409357 | V8: 17.4 | W8: 0 | X8: =V8/(E8+W8) -> 0.0218923 | Y8: 125.2 | Z8: 0.6 | AA8: =Y8/(E8+Z8) -> 0.15740508 | AB8: 77.4 | AC8: 0 | AD8: =AB8/(E8+AC8) -> 0.097382989 | AE8: 36 | AF8: =AE8/R8 -> 0.070175439
A9: 2025-7/7~7/11 | B9: 总计 | D9: =D7+D8 -> 490.6 | E9: =E7+E8 -> 1891.8 | F9: =F7+F8 -> 1628 | G9: =F9/E9 -> 0.86055608 | H9: =(I9+L9+O9+R9+T9+V9+Y9+AB9+AE9)/F9 -> 1.632801 | I9: =I7+I8 -> 87 | J9: =J7+J8 -> 0.4 | K9: =I9/(E9+J9) -> 0.045978226 | L9: =L7+L8 -> 15 | N9: =L9/(E9+M9) -> 0.0079289565 | O9: =O7+O8 -> 544 | P9: =P7+P8 -> 544 | Q9: =O9/(E9+P9) -> 0.22333525 | R9: =R7+R8 -> 1292.8 | S9: =R9/E9 -> 0.68337034 | T9: =T7+T8 -> 262.2 | U9: =T9/R9 -> 0.20281559 | V9: =V7+V8 -> 28.4 | X9: =V9/(E9+W9) -> 0.015012158 | Y9: =Y7+Y8 -> 210 | Z9: =Z7+Z8 -> 2.8 | AA9: =Y9/(E9+Z9) -> 0.11084134 | AB9: =AB7+AB8 -> 136.8 | AD9: =AB9/(E9+AC9) -> 0.072312084 | AE9: =AE7+AE8 -> 82 | AF9: =AE9/R9 -> 0.063428218
A10: 2025-7/14~7/18 | B10: 印度/巴基斯坦 | D10: 300.9 | E10: 1124 | F10: 970.4 | G10: =F10/E10 -> 0.8633452 | H10: =(I10+L10+O10+R10+T10+V10+Y10+AB10+AE10)/F10 -> 1.5684254 | I10: 41.8 | J10: 0.4 | K10: =I10/(E10+J10) -> 0.037175382 | L10: 6.6 | M10: 0 | N10: =L10/(E10+M10) -> 0.0058718861 | O10: 346.6 | P10: 346.6 | Q10: =O10/(E10+P10) -> 0.23568611 | R10: 827.4 | S10: =R10/E10 -> 0.736121 | T10: 112.4 | U10: =T10/R10 -> 0.13584723 | V10: 11.6 | W10: 0 | X10: =V10/(E10+W10) -> 0.010320285 | Y10: 75.4 | Z10: 1.4 | AA10: =Y10/(E10+Z10) -> 0.066998401 | AB10: 53 | AC10: 0 | AD10: =AB10/(E10+AC10) -> 0.047153025 | AE10: 47.2 | AF10: =AE10/R10 -> 0.057046169
A11: 2025-7/14~7/18 | B11: 印尼 | D11: 267 | E11: 836.6 | F11: 741.4 | G11: =F11/E11 -> 0.88620607 | H11: =(I11+L11+O11+R11+T11+V11+Y11+AB11+AE11)/F11 -> 1.7914756 | I11: 55.4 | J11: 0.4 | K11: =I11/(E11+J11) -> 0.066188769 | L11: 13.8 | M11: 0 | N11: =L11/(E11+M11) -> 0.016495338 | O11: 260.6 | P11: 260.6 | Q11: =O11/(E11+P11) -> 0.23751367 | R11: 571.2 | S11: =R11/E11 -> 0.68276357 | T11: 173.2 | U11: =T11/R11 -> 0.30322129 | V11: 20.8 | W11: 0 | X11: =V11/(E11+W11) -> 0.024862539 | Y11: 114 | Z11: 2.6 | AA11: =Y11/(E11+Z11) -> 0.13584366 | AB11: 79.8 | AC11: 0 | AD11: =AB11/(E11+AC11) -> 0.095386087 | AE11: 39.4 | AF11: =AE11/R11 -> 0.068977591
A12: 2025-7/14~7/18 | B12: 总计 | D12: =D10+D11 -> 567.9 | E12: =E10+E11 -> 1960.6 | F12: =F10+F11 -> 1711.8 | G12: =F12/E12 -> 0.87310007 | H12: =(I12+L12+O12+R12+T12+V12+Y12+AB12+AE12)/F12 -> 1.665031 | I12: =I10+I11 -> 97.2 | J12: =J10+J11 -> 0.8 | K12: =I12/(E12+J12) -> 0.049556439 | L12: =L10+L11 -> 20.4 | N12: =L12/(E12+M12) -> 0.010404978 | O12: =O10+O11 -> 607.2 | P12: =P10+P11 -> 607.2 | Q12: =O12/(E12+P12) -> 0.23646701 | R12: =R10+R11 -> 1398.6 | S12: =R12/E12 -> 0.71335306 | T12: =T10+T11 -> 285.6 | U12: =T12/R12 -> 0.2042042 | V12: =V10+V11 -> 32.4 | X12: =V12/(E12+W12) -> 0.016525553 | Y12: =Y10+Y11 -> 189.4 | Z12: =Z10+Z11 -> 4 | AA12: =Y12/(E12+Z12) -> 0.096406393 | AB12: =AB10+AB11 -> 132.8 | AD12: =AB12/(E12+AC12) -> 0.067734367 | AE12: =AE10+AE11 -> 86.6 | AF12: =AE12/R12 -> 0.061919062
A13: 2025-7/21~7/25 | B13: 印度/巴基斯坦 | D13: 291.3 | E13: 1191.6 | F13: 1029.8 | G13: =F13/E13 -> 0.86421618 | H13: =(I13+L13+O13+R13+T13+V13+Y13+AB13+AE13)/F13 -> 1.5604972 | I13: 40.8 | J13: 0.2 | K13: =I13/(E13+J13) -> 0.034233932 | L13: 4.4 | M13: 0 | N13: =L13/(E13+M13) -> 0.0036925143 | O13: 348.6 | P13: 348.6 | Q13: =O13/(E13+P13) -> 0.22633424 | R13: 877.4 | S13: =R13/E13 -> 0.73632091 | T13: 121.8 | U13: =T13/R13 -> 0.13881924 | V13: 14.4 | W13: 0 | X13: =V13/(E13+W13) -> 0.012084592 | Y13: 88 | Z13: 1.6 | AA13: =Y13/(E13+Z13) -> 0.073751257 | AB13: 60.8 | AC13: 0 | AD13: =AB13/(E13+AC13) -> 0.051023834 | AE13: 50.8 | AF13: =AE13/R13 -> 0.057898336
A14: 2025-7/21~7/25 | B14: 印尼 | D14: 248.2 | E14: 842.6 | F14: 739.8 | G14: =F14/E14 -> 0.87799668 | H14: =(I14+L14+O14+R14+T14+V14+Y14+AB14+AE14)/F14 -> 1.7780481 | I14: 54.4 | J14: 0 | K14: =I14/(E14+J14) -> 0.06456207 | L14: 11.8 | M14: 0 | N14: =L14/(E14+M14) -> 0.014004272 | O14: 253 | P14: 253 | Q14: =O14/(E14+P14) -> 0.23092369 | R14: 563.4 | S14: =R14/E14 -> 0.66864467 | T14: 177.2 | U14: =T14/R14 -> 0.31451899 | V14: 14 | W14: 0 | X14: =V14/(E14+W14) -> 0.016615239 | Y14: 108.8 | Z14: 1.2 | AA14: =Y14/(E14+Z14) -> 0.12894051 | AB14: 94 | AC14: 0 | AD14: =AB14/(E14+AC14) -> 0.11155946 | AE14: 38.8 | AF14: =AE14/R14 -> 0.06886759
A15: 2025-7/21~7/25 | B15: 总计 | D15: =D13+D14 -> 539.5 | E15: =E13+E14 -> 2034.2 | F15: =F13+F14 -> 1769.6 | G15: =F15/E15 -> 0.86992429 | H15: =(I15+L15+O15+R15+T15+V15+Y15+AB15+AE15)/F15 -> 1.6514467 | I15: =I13+I14 -> 95.2 | J15: =J13+J14 -> 0.2 | K15: =I15/(E15+J15) -> 0.046795124 | L15: =L13+L14 -> 16.2 | N15: =L15/(E15+M15) -> 0.0079638187 | O15: =O13+O14 -> 601.6 | P15: =P13+P14 -> 601.6 | Q15: =O15/(E15+P15) -> 0.2282419 | R15: =R13+R14 -> 1440.8 | S15: =R15/E15 -> 0.70828827 | T15: =T13+T14 -> 299 | U15: =T15/R15 -> 0.2075236 | V15: =V13+V14 -> 28.4 | X15: =V15/(E15+W15) -> 0.013961262 | Y15: =Y13+Y14 -> 196.8 | Z15: =Z13+Z14 -> 2.8 | AA15: =Y15/(E15+Z15) -> 0.096612666 | AB15: =AB13+AB14 -> 154.8 | AD15: =AB15/(E15+AC15) -> 0.076098712 | AE15: =AE13+AE14 -> 89.6 | AF15: =AE15/R15 -> 0.062187674
A16: 2025-7/28~8/1 | B16: 印度/巴基斯坦 | D16: 293.4 | E16: 1334.8 | F16: 1123.4 | G16: =F16/E16 -> 0.84162421 | H16: =(I16+L16+O16+R16+T16+V16+Y16+AB16+AE16)/F16 -> 1.5127292 | I16: 41 | J16: 0.2 | K16: =I16/(E16+J16) -> 0.03071161 | L16: 5.2 | M16: 0 | N16: =L16/(E16+M16) -> 0.0038957147 | O16: 355.8 | P16: 355.8 | Q16: =O16/(E16+P16) -> 0.21045783 | R16: 964.4 | S16: =R16/E16 -> 0.72250524 | T16: 127.4 | U16: =T16/R16 -> 0.13210286 | V16: 12.6 | W16: 0 | X16: =V16/(E16+W16) -> 0.0094396164 | Y16: 78.4 | Z16: 1.8 | AA16: =Y16/(E16+Z16) -> 0.058656292 | AB16: 67.8 | AC16: 0 | AD16: =AB16/(E16+AC16) -> 0.050794126 | AE16: 46.8 | AF16: =AE16/R16 -> 0.048527582
A17: 2025-7/28~8/1 | B17: 印尼 | D17: 230.1 | E17: 911.4 | F17: 736 | G17: =F17/E17 -> 0.80754883 | H17: =(I17+L17+O17+R17+T17+V17+Y17+AB17+AE17)/F17 -> 1.7013587 | I17: 52.4 | J17: 0.2 | K17: =I17/(E17+J17) -> 0.057481351 | L17: 10.6 | M17: 0 | N17: =L17/(E17+M17) -> 0.011630459 | O17: 227.6 | P17: 227.6 | Q17: =O17/(E17+P17) -> 0.19982441 | R17: 545.8 | S17: =R17/E17 -> 0.5988589 | T17: 165 | U17: =T17/R17 -> 0.30230854 | V17: 24 | W17: 0 | X17: =V17/(E17+W17) -> 0.026333114 | Y17: 117.8 | Z17: 2.4 | AA17: =Y17/(E17+Z17) -> 0.12891223 | AB17: 77 | AC17: 0 | AD17: =AB17/(E17+AC17) -> 0.084485407 | AE17: 32 | AF17: =AE17/R17 -> 0.058629535
A18: 2025-7/28~8/1 | B18: 总计 | D18: =D16+D17 -> 523.5 | E18: =E16+E17 -> 2246.2 | F18: =F16+F17 -> 1859.4 | G18: =F18/E18 -> 0.82779806 | H18: =(I18+L18+O18+R18+T18+V18+Y18+AB18+AE18)/F18 -> 1.5873938 | I18: =I16+I17 -> 93.4 | J18: =J16+J17 -> 0.4 | K18: =I18/(E18+J18) -> 0.041573934 | L18: =L16+L17 -> 15.8 | N18: =L18/(E18+M18) -> 0.007034102 | O18: =O16+O17 -> 583.4 | P18: =P16+P17 -> 583.4 | Q18: =O18/(E18+P18) -> 0.20617755 | R18: =R16+R17 -> 1510.2 | S18: =R18/E18 -> 0.6723355 | T18: =T16+T17 -> 292.4 | U18: =T18/R18 -> 0.19361674 | V18: =V16+V17 -> 36.6 | X18: =V18/(E18+W18) -> 0.016294186 | Y18: =Y16+Y17 -> 196.2 | Z18: =Z16+Z17 -> 4.2 | AA18: =Y18/(E18+Z18) -> 0.087184501 | AB18: =AB16+AB17 -> 144.8 | AD18: =AB18/(E18+AC18) -> 0.064464429 | AE18: =AE16+AE17 -> 78.8 | AF18: =AE18/R18 -> 0.052178519
A19: 2025-8/4~8/8 | B19: 印度/巴基斯坦 | D19: 291.3 | E19: 1143.8 | F19: 971.2 | G19: =F19/E19 -> 0.84909949 | H19: =(I19+L19+O19+R19+T19+V19+Y19+AB19+AE19)/F19 -> 1.5928748 | I19: 31.2 | J19: 0 | K19: =I19/(E19+J19) -> 0.027277496 | L19: 6.4 | M19: 0 | N19: =L19/(E19+M19) -> 0.0055953838 | O19: 351 | P19: 351 | Q19: =O19/(E19+P19) -> 0.23481402 | R19: 830 | S19: =R19/E19 -> 0.72565134 | T19: 123.6 | U19: =T19/R19 -> 0.14891566 | V19: 11.2 | W19: 0 | X19: =V19/(E19+W19) -> 0.0097919217 | Y19: 84.8 | Z19: 1.4 | AA19: =Y19/(E19+Z19) -> 0.074048201 | AB19: 60 | AC19: 0 | AD19: =AB19/(E19+AC19) -> 0.052456723 | AE19: 48.8 | AF19: =AE19/R19 -> 0.058795181
A20: 2025-8/4~8/8 | B20: 印尼 | D20: 240.4 | E20: 837.4 | F20: 713 | G20: =F20/E20 -> 0.85144495 | H20: =(I20+L20+O20+R20+T20+V20+Y20+AB20+AE20)/F20 -> 1.7525947 | I20: 53.2 | J20: 0.6 | K20: =I20/(E20+J20) -> 0.063484487 | L20: 11.6 | M20: 0 | N20: =L20/(E20+M20) -> 0.0138524 | O20: 254.8 | P20: 254.8 | Q20: =O20/(E20+P20) -> 0.23329061 | R20: 539 | S20: =R20/E20 -> 0.64365894 | T20: 154.6 | U20: =T20/R20 -> 0.28682746 | V20: 20.2 | W20: 0 | X20: =V20/(E20+W20) -> 0.024122283 | Y20: 106.2 | Z20: 1.2 | AA20: =Y20/(E20+Z20) -> 0.12663964 | AB20: 74 | AC20: 0 | AD20: =AB20/(E20+AC20) -> 0.08836876 | AE20: 36 | AF20: =AE20/R20 -> 0.066790353
A21: 2025-8/4~8/8 | B21: 总计 | D21: =D19+D20 -> 531.7 | E21: =E19+E20 -> 1981.2 | F21: =F19+F20 -> 1684.2 | G21: =F21/E21 -> 0.85009085 | H21: =(I21+L21+O21+R21+T21+V21+Y21+AB21+AE21)/F21 -> 1.6604916 | I21: =I19+I20 -> 84.4 | J21: =J19+J20 -> 0.6 | K21: =I21/(E21+J21) -> 0.042587547 | L21: =L19+L20 -> 18 | N21: =L21/(E21+M21) -> 0.0090854028 | O21: =O19+O20 -> 605.8 | P21: =P19+P20 -> 605.8 | Q21: =O21/(E21+P21) -> 0.23417085 | R21: =R19+R20 -> 1369 | S21: =R21/E21 -> 0.69099536 | T21: =T19+T20 -> 278.2 | U21: =T21/R21 -> 0.20321402 | V21: =V19+V20 -> 31.4 | X21: =V21/(E21+W21) -> 0.01584898 | Y21: =Y19+Y20 -> 191 | Z21: =Z19+Z20 -> 2.6 | AA21: =Y21/(E21+Z21) -> 0.096279867 | AB21: =AB19+AB20 -> 134 | AD21: =AB21/(E21+AC21) -> 0.067635776 | AE21: =AE19+AE20 -> 84.8 | AF21: =AE21/R21 -> 0.061943024
A22: 2025-8/11~8/15 | B22: 印度/巴基斯坦 | D22: 268.2 | E22: 1138.6 | F22: 923.4 | G22: =F22/E22 -> 0.81099596 | H22: =(I22+L22+O22+R22+T22+V22+Y22+AB22+AE22)/F22 -> 1.5789474 | I22: 33.2 | J22: 0.2 | K22: =I22/(E22+J22) -> 0.029153495 | L22: 5.8 | M22: 0 | N22: =L22/(E22+M22) -> 0.0050939751 | O22: 334.2 | P22: 334.2 | Q22: =O22/(E22+P22) -> 0.22691472 | R22: 784.6 | S22: =R22/E22 -> 0.68909187 | T22: 112.6 | U22: =T22/R22 -> 0.14351262 | V22: 8.6 | W22: 0 | X22: =V22/(E22+W22) -> 0.0075531354 | Y22: 87.6 | Z22: 1.8 | AA22: =Y22/(E22+Z22) -> 0.076815153 | AB22: 50.2 | AC22: 0 | AD22: =AB22/(E22+AC22) -> 0.044089232 | AE22: 41.2 | AF22: =AE22/R22 -> 0.052510834
A23: 2025-8/11~8/15 | B23: 印尼 | D23: 221.4 | E23: 907.6 | F23: 693.2 | G23: =F23/E23 -> 0.76377259 | H23: =(I23+L23+O23+R23+T23+V23+Y23+AB23+AE23)/F23 -> 1.7152337 | I23: 50.6 | J23: 0.2 | K23: =I23/(E23+J23) -> 0.05573915 | L23: 15.4 | M23: 0 | N23: =L23/(E23+M23) -> 0.016967827 | O23: 230.8 | P23: 230.8 | Q23: =O23/(E23+P23) -> 0.20274069 | R23: 521.4 | S23: =R23/E23 -> 0.57448215 | T23: 142 | U23: =T23/R23 -> 0.27234369 | V23: 15 | W23: 0 | X23: =V23/(E23+W23) -> 0.016527104 | Y23: 109.2 | Z23: 1.2 | AA23: =Y23/(E23+Z23) -> 0.12015845 | AB23: 69 | AC23: 0 | AD23: =AB23/(E23+AC23) -> 0.07602468 | AE23: 35.6 | AF23: =AE23/R23 -> 0.068277714
A24: 2025-8/11~8/15 | B24: 总计 | D24: =D22+D23 -> 489.6 | E24: =E22+E23 -> 2046.2 | F24: =F22+F23 -> 1616.6 | G24: =F24/E24 -> 0.79004985 | H24: =(I24+L24+O24+R24+T24+V24+Y24+AB24+AE24)/F24 -> 1.6373871 | I24: =I22+I23 -> 83.8 | J24: =J22+J23 -> 0.4 | K24: =I24/(E24+J24) -> 0.040945959 | L24: =L22+L23 -> 21.2 | N24: =L24/(E24+M24) -> 0.010360669 | O24: =O22+O23 -> 565 | P24: =P22+P23 -> 565 | Q24: =O24/(E24+P24) -> 0.21637561 | R24: =R22+R23 -> 1306 | S24: =R24/E24 -> 0.63825628 | T24: =T22+T23 -> 254.6 | U24: =T24/R24 -> 0.1949464 | V24: =V22+V23 -> 23.6 | X24: =V24/(E24+W24) -> 0.011533574 | Y24: =Y22+Y23 -> 196.8 | Z24: =Z22+Z23 -> 3 | AA24: =Y24/(E24+Z24) -> 0.096037478 | AB24: =AB22+AB23 -> 119.2 | AD24: =AB24/(E24+AC24) -> 0.058254325 | AE24: =AE22+AE23 -> 76.8 | AF24: =AE24/R24 -> 0.058805513
A25: 2025-8/18~8/22 | B25: 印度/巴基斯坦 | D25: 277.6 | E25: 1056.6 | F25: 887.8 | G25: =F25/E25 -> 0.84024229 | H25: =(I25+L25+O25+R25+T25+V25+Y25+AB25+AE25)/F25 -> 1.5814373 | I25: 37.6 | J25: 0 | K25: =I25/(E25+J25) -> 0.035585841 | L25: 2.6 | M25: 0 | N25: =L25/(E25+M25) -> 0.0024607231 | O25: 335.8 | P25: 335.8 | Q25: =O25/(E25+P25) -> 0.24116633 | R25: 753.2 | S25: =R25/E25 -> 0.71285255 | T25: 108.2 | U25: =T25/R25 -> 0.14365374 | V25: 6.8 | W25: 0 | X25: =V25/(E25+W25) -> 0.0064357373 | Y25: 69.6 | Z25: 0.8 | AA25: =Y25/(E25+Z25) -> 0.065821827 | AB25: 47.8 | AC25: 0 | AD25: =AB25/(E25+AC25) -> 0.045239447 | AE25: 42.4 | AF25: =AE25/R25 -> 0.056293149
A26: 2025-8/18~8/22 | B26: 印尼 | D26: 231.2 | E26: 903 | F26: 669.6 | G26: =F26/E26 -> 0.74152824 | H26: =(I26+L26+O26+R26+T26+V26+Y26+AB26+AE26)/F26 -> 1.7132616 | I26: 45.8 | J26: 0 | K26: =I26/(E26+J26) -> 0.050719823 | L26: 21.2 | M26: 0 | N26: =L26/(E26+M26) -> 0.023477298 | O26: 222.8 | P26: 222.8 | Q26: =O26/(E26+P26) -> 0.19790371 | R26: 493.6 | S26: =R26/E26 -> 0.54662237 | T26: 148.4 | U26: =T26/R26 -> 0.3006483 | V26: 11.2 | W26: 0 | X26: =V26/(E26+W26) -> 0.012403101 | Y26: 109.4 | Z26: 1.2 | AA26: =Y26/(E26+Z26) -> 0.12099093 | AB26: 64.8 | AC26: 0 | AD26: =AB26/(E26+AC26) -> 0.071760797 | AE26: 30 | AF26: =AE26/R26 -> 0.060777958
A27: 2025-8/18~8/22 | B27: 总计 | D27: =D25+D26 -> 508.8 | E27: =E25+E26 -> 1959.6 | F27: =F25+F26 -> 1557.4 | G27: =F27/E27 -> 0.79475403 | H27: =(I27+L27+O27+R27+T27+V27+Y27+AB27+AE27)/F27 -> 1.6381148 | I27: =I25+I26 -> 83.4 | J27: =J25+J26 -> 0 | K27: =I27/(E27+J27) -> 0.042559706 | L27: =L25+L26 -> 23.8 | N27: =L27/(E27+M27) -> 0.012145336 | O27: =O25+O26 -> 558.6 | P27: =P25+P26 -> 558.6 | Q27: =O27/(E27+P27) -> 0.22182511 | R27: =R25+R26 -> 1246.8 | S27: =R27/E27 -> 0.6362523 | T27: =T25+T26 -> 256.6 | U27: =T27/R27 -> 0.20580687 | V27: =V25+V26 -> 18 | X27: =V27/(E27+W27) -> 0.0091855481 | Y27: =Y25+Y26 -> 179 | Z27: =Z25+Z26 -> 2 | AA27: =Y27/(E27+Z27) -> 0.091252039 | AB27: =AB25+AB26 -> 112.6 | AD27: =AB27/(E27+AC27) -> 0.057460706 | AE27: =AE25+AE26 -> 72.4 | AF27: =AE27/R27 -> 0.058068656
A28: 2025-8/25~8/29 | B28: 印度/巴基斯坦 | D28: 316.7 | E28: 1217.8 | F28: 1022.6 | G28: =F28/E28 -> 0.83971095 | H28: =(I28+L28+O28+R28+T28+V28+Y28+AB28+AE28)/F28 -> 1.6262468 | I28: 43.8 | J28: 0.4 | K28: =I28/(E28+J28) -> 0.035954687 | L28: 7.4 | M28: 0 | N28: =L28/(E28+M28) -> 0.0060765315 | O28: 399.2 | P28: 399.2 | Q28: =O28/(E28+P28) -> 0.24687693 | R28: 862 | S28: =R28/E28 -> 0.7078338 | T28: 137.2 | U28: =T28/R28 -> 0.15916473 | V28: 12.2 | W28: 0 | X28: =V28/(E28+W28) -> 0.010018065 | Y28: 91.2 | Z28: 2 | AA28: =Y28/(E28+Z28) -> 0.074766355 | AB28: 67.2 | AC28: 0 | AD28: =AB28/(E28+AC28) -> 0.055181475 | AE28: 42.8 | AF28: =AE28/R28 -> 0.049651972
A29: 2025-8/25~8/29 | B29: 印尼 | D29: 225.9 | E29: 753.6 | F29: 657.4 | G29: =F29/E29 -> 0.87234607 | H29: =(I29+L29+O29+R29+T29+V29+Y29+AB29+AE29)/F29 -> 1.7547916 | I29: 48.4 | J29: 0.6 | K29: =I29/(E29+J29) -> 0.064173959 | L29: 17.2 | M29: 0 | N29: =L29/(E29+M29) -> 0.022823779 | O29: 223.2 | P29: 223.2 | Q29: =O29/(E29+P29) -> 0.22850123 | R29: 483.6 | S29: =R29/E29 -> 0.64171975 | T29: 149.8 | U29: =T29/R29 -> 0.30976013 | V29: 20.4 | W29: 0 | X29: =V29/(E29+W29) -> 0.027070064 | Y29: 102.2 | Z29: 1.6 | AA29: =Y29/(E29+Z29) -> 0.13532839 | AB29: 74.6 | AC29: 0 | AD29: =AB29/(E29+AC29) -> 0.098991507 | AE29: 34.2 | AF29: =AE29/R29 -> 0.070719603
A30: 2025-8/25~8/29 | B30: 总计 | D30: =D28+D29 -> 542.6 | E30: =E28+E29 -> 1971.4 | F30: =F28+F29 -> 1680 | G30: =F30/E30 -> 0.85218626 | H30: =(I30+L30+O30+R30+T30+V30+Y30+AB30+AE30)/F30 -> 1.6765476 | I30: =I28+I29 -> 92.2 | J30: =J28+J29 -> 1 | K30: =I30/(E30+J30) -> 0.046745082 | L30: =L28+L29 -> 24.6 | N30: =L30/(E30+M30) -> 0.012478442 | O30: =O28+O29 -> 622.4 | P30: =P28+P29 -> 622.4 | Q30: =O30/(E30+P30) -> 0.23995682 | R30: =R28+R29 -> 1345.6 | S30: =R30/E30 -> 0.68256062 | T30: =T28+T29 -> 287 | U30: =T30/R30 -> 0.21328775 | V30: =V28+V29 -> 32.6 | X30: =V30/(E30+W30) -> 0.016536472 | Y30: =Y28+Y29 -> 193.4 | Z30: =Z28+Z29 -> 3.6 | AA30: =Y30/(E30+Z30) -> 0.097924051 | AB30: =AB28+AB29 -> 141.8 | AD30: =AB30/(E30+AC30) -> 0.071928579 | AE30: =AE28+AE29 -> 77 | AF30: =AE30/R30 -> 0.057223543
A31: 2025-9/1~9/5 | B31: 印度/巴基斯坦 | D31: 274 | E31: 1140.4 | F31: 897.8 | G31: =F31/E31 -> 0.78726763 | H31: =(I31+L31+O31+R31+T31+V31+Y31+AB31+AE31)/F31 -> 1.6003564 | I31: 36.8 | J31: 0.2 | K31: =I31/(E31+J31) -> 0.032263721 | L31: 5.6 | M31: 0 | N31: =L31/(E31+M31) -> 0.0049105577 | O31: 343.2 | P31: 343.2 | Q31: =O31/(E31+P31) -> 0.2313292 | R31: 765.6 | S31: =R31/E31 -> 0.67134339 | T31: 110.4 | U31: =T31/R31 -> 0.14420063 | V31: 8.2 | W31: 0 | X31: =V31/(E31+W31) -> 0.0071904595 | Y31: 68.8 | Z31: 0.6 | AA31: =Y31/(E31+Z31) -> 0.060297984 | AB31: 59.8 | AC31: 0 | AD31: =AB31/(E31+AC31) -> 0.052437741 | AE31: 38.4 | AF31: =AE31/R31 -> 0.05015674
A32: 2025-9/1~9/5 | B32: 印尼 | D32: 209.7 | E32: 726.2 | F32: 618 | G32: =F32/E32 -> 0.85100523 | H32: =(I32+L32+O32+R32+T32+V32+Y32+AB32+AE32)/F32 -> 1.7647249 | I32: 47.8 | J32: 0.2 | K32: =I32/(E32+J32) -> 0.065803965 | L32: 17.2 | M32: 0 | N32: =L32/(E32+M32) -> 0.023684935 | O32: 212.2 | P32: 212.2 | Q32: =O32/(E32+P32) -> 0.22612958 | R32: 460.8 | S32: =R32/E32 -> 0.63453594 | T32: 145.8 | U32: =T32/R32 -> 0.31640625 | V32: 14 | W32: 0 | X32: =V32/(E32+W32) -> 0.019278436 | Y32: 92.2 | Z32: 1.4 | AA32: =Y32/(E32+Z32) -> 0.12671798 | AB32: 68.6 | AC32: 0 | AD32: =AB32/(E32+AC32) -> 0.094464335 | AE32: 32 | AF32: =AE32/R32 -> 0.069444444
A33: 2025-9/1~9/5 | B33: 总计 | D33: =D31+D32 -> 483.7 | E33: =E31+E32 -> 1866.6 | F33: =F31+F32 -> 1515.8 | G33: =F33/E33 -> 0.81206472 | H33: =(I33+L33+O33+R33+T33+V33+Y33+AB33+AE33)/F33 -> 1.6673704 | I33: =I31+I32 -> 84.6 | J33: =J31+J32 -> 0.4 | K33: =I33/(E33+J33) -> 0.045313337 | L33: =L31+L32 -> 22.8 | N33: =L33/(E33+M33) -> 0.012214722 | O33: =O31+O32 -> 555.4 | P33: =P31+P32 -> 555.4 | Q33: =O33/(E33+P33) -> 0.22931462 | R33: =R31+R32 -> 1226.4 | S33: =R33/E33 -> 0.65702347 | T33: =T31+T32 -> 256.2 | U33: =T33/R33 -> 0.20890411 | V33: =V31+V32 -> 22.2 | X33: =V33/(E33+W33) -> 0.011893282 | Y33: =Y31+Y32 -> 161 | Z33: =Z31+Z32 -> 2 | AA33: =Y33/(E33+Z33) -> 0.086160762 | AB33: =AB31+AB32 -> 128.4 | AD33: =AB33/(E33+AC33) -> 0.068788171 | AE33: =AE31+AE32 -> 70.4 | AF33: =AE33/R33 -> 0.057403783
A34: 2025-9/8~9/12 | B34: 印度/巴基斯坦 | D34: 310.1 | E34: 1204.8 | F34: 999 | G34: =F34/E34 -> 0.82918327 | H34: =(I34+L34+O34+R34+T34+V34+Y34+AB34+AE34)/F34 -> 1.6208208 | I34: 35.8 | J34: 0.2 | K34: =I34/(E34+J34) -> 0.029709544 | L34: 7.8 | M34: 0 | N34: =L34/(E34+M34) -> 0.0064741036 | O34: 402.8 | P34: 402.8 | Q34: =O34/(E34+P34) -> 0.25055984 | R34: 858.6 | S34: =R34/E34 -> 0.7126494 | T34: 121.8 | U34: =T34/R34 -> 0.14185884 | V34: 10.4 | W34: 0 | X34: =V34/(E34+W34) -> 0.0086321381 | Y34: 60.8 | Z34: 1.2 | AA34: =Y34/(E34+Z34) -> 0.050414594 | AB34: 73.2 | AC34: 0 | AD34: =AB34/(E34+AC34) -> 0.060756972 | AE34: 48 | AF34: =AE34/R34 -> 0.055904962
A35: 2025-9/8~9/12 | B35: 印尼 | D35: 216.3 | E35: 754.8 | F35: 647.8 | G35: =F35/E35 -> 0.85824059 | H35: =(I35+L35+O35+R35+T35+V35+Y35+AB35+AE35)/F35 -> 1.7474529 | I35: 45.4 | J35: 0.4 | K35: =I35/(E35+J35) -> 0.060116525 | L35: 21.4 | M35: 0 | N35: =L35/(E35+M35) -> 0.028351881 | O35: 213.6 | P35: 213.6 | Q35: =O35/(E35+P35) -> 0.22057001 | R35: 479.6 | S35: =R35/E35 -> 0.63540011 | T35: 143.2 | U35: =T35/R35 -> 0.29858215 | V35: 14.8 | W35: 0 | X35: =V35/(E35+W35) -> 0.019607843 | Y35: 102.6 | Z35: 1.2 | AA35: =Y35/(E35+Z35) -> 0.13571429 | AB35: 82 | AC35: 0 | AD35: =AB35/(E35+AC35) -> 0.10863805 | AE35: 29.4 | AF35: =AE35/R35 -> 0.061301084
A36: 2025-9/8~9/12 | B36: 总计 | D36: =D34+D35 -> 526.4 | E36: =E34+E35 -> 1959.6 | F36: =F34+F35 -> 1646.8 | G36: =F36/E36 -> 0.84037559 | H36: =(I36+L36+O36+R36+T36+V36+Y36+AB36+AE36)/F36 -> 1.670634 | I36: =I34+I35 -> 81.2 | J36: =J34+J35 -> 0.6 | K36: =I36/(E36+J36) -> 0.041424344 | L36: =L34+L35 -> 29.2 | N36: =L36/(E36+M36) -> 0.014901 | O36: =O34+O35 -> 616.4 | P36: =P34+P35 -> 616.4 | Q36: =O36/(E36+P36) -> 0.23928571 | R36: =R34+R35 -> 1338.2 | S36: =R36/E36 -> 0.68289447 | T36: =T34+T35 -> 265 | U36: =T36/R36 -> 0.1980272 | V36: =V34+V35 -> 25.2 | X36: =V36/(E36+W36) -> 0.012859767 | Y36: =Y34+Y35 -> 163.4 | Z36: =Z34+Z35 -> 2.4 | AA36: =Y36/(E36+Z36) -> 0.083282365 | AB36: =AB34+AB35 -> 155.2 | AD36: =AB36/(E36+AC36) -> 0.079199837 | AE36: =AE34+AE35 -> 77.4 | AF36: =AE36/R36 -> 0.057838888
A37: 2025-9/15~9/19 | B37: 印度/巴基斯坦 | D37: 324.8 | E37: 1155.2 | F37: 965.2 | G37: =F37/E37 -> 0.83552632 | H37: =(I37+L37+O37+R37+T37+V37+Y37+AB37+AE37)/F37 -> 1.6479486 | I37: 35 | J37: 1 | K37: =I37/(E37+J37) -> 0.030271579 | L37: 6.2 | M37: 0 | N37: =L37/(E37+M37) -> 0.005367036 | O37: 398.6 | P37: 398.6 | Q37: =O37/(E37+P37) -> 0.25653237 | R37: 823.6 | S37: =R37/E37 -> 0.71295014 | T37: 125.2 | U37: =T37/R37 -> 0.15201554 | V37: 9.6 | W37: 0 | X37: =V37/(E37+W37) -> 0.0083102493 | Y37: 75.6 | Z37: 1.4 | AA37: =Y37/(E37+Z37) -> 0.065363998 | AB37: 72.6 | AC37: 0 | AD37: =AB37/(E37+AC37) -> 0.06284626 | AE37: 44.2 | AF37: =AE37/R37 -> 0.053666829
